<?xml version="1.0" ?>
<robot name="converted_robot">
   <link name="hand_root">
      <inertial>
         <origin xyz="0.0 0.0 0.0" rpy="0.0 0.0 0.0"/>
         <mass value="0.0"/>
         <inertia ixx="0.0" iyy="0.0" izz="0.0" ixy="0" ixz="0" iyz="0"/>
      </inertial>
   </link>
   <link name="palm">
      <inertial>
         <origin xyz="0.0031931161538907675 -0.0006744956817974197 -0.015141641629351442" rpy="0.11369803949052038 0.0015109688649919129 1.5487764199118472"/>
         <mass value="0.15922386065672636"/>
         <inertia ixx="0.00012041487596921829" iyy="8.59196043876551e-05" izz="4.1572032560976865e-05" ixy="0" ixz="0" iyz="0"/>
      </inertial>
      <visual name="palm_tower">
         <origin xyz="0.0031931161538907675 -0.0006744956817974197 -0.015141641629351442" rpy="0.11369803949052038 0.001510968864992135 1.5487764199118472"/>
         <geometry>
            <mesh filename="package://viz/models/orca1_hand/urdf/converted_palm_tower.stl"/>
         </geometry>
         <material name="white"/>
      </visual>
   </link>
   <link name="root2palm_fixed_jointbody">
      <inertial>
         <origin xyz="0.0 0.0 0.0" rpy="0.0 0.0 0.0"/>
         <mass value="0.001"/>
         <inertia ixx="1e-09" iyy="1e-09" izz="1e-09" ixy="0" ixz="0" iyz="0"/>
      </inertial>
   </link>
   <joint type="fixed" name="root2palm_fixed">
      <parent link="hand_root"/>
      <child link="root2palm_fixed_jointbody"/>
      <origin xyz="0.193999986406645 -3.686916491009634e-05 0.00199999999999996" rpy="0.0007373833650254783 1.5707963267948966 0.0"/>
   </joint>
   <joint type="fixed" name="root2palm_fixed_offset">
      <parent link="root2palm_fixed_jointbody"/>
      <child link="palm"/>
      <origin xyz="-0.0 -0.0 -0.0" rpy="0.0 0.0 0.0"/>
   </joint>
   <link name="index_um">
      <inertial>
         <origin xyz="0.006732763304155957 4.001088863436687e-09 -2.0258619702217643e-05" rpy="-3.131684616200393 -1.561854856603541 -0.009908433449917098"/>
         <mass value="0.002607186033198995"/>
         <inertia ixx="1.3807074528604164e-07" iyy="1.1778104249469416e-07" izz="6.49217043247213e-08" ixy="0" ixz="0" iyz="0"/>
      </inertial>
      <visual name="index_um">
         <origin xyz="0.006732763304155957 4.001088863436687e-09 -2.0258619702217643e-05" rpy="-3.131684616200393 -1.561854856603541 -0.009908433449916876"/>
         <geometry>
            <mesh filename="package://viz/models/orca1_hand/urdf/converted_index_um.stl"/>
         </geometry>
         <material name="white"/>
      </visual>
   </link>
   <link name="index_abd_jointbody">
      <inertial>
         <origin xyz="0.0 0.0 0.0" rpy="0.0 0.0 0.0"/>
         <mass value="0.001"/>
         <inertia ixx="1e-09" iyy="1e-09" izz="1e-09" ixy="0" ixz="0" iyz="0"/>
      </inertial>
   </link>
   <joint type="revolute" name="index_abd">
      <parent link="palm"/>
      <child link="index_abd_jointbody"/>
      <origin xyz="-0.0220268982915701 0.0015684105070722626 0.03555822504310243" rpy="1.6579894511737647 1.3961154673834115 -7.447055239240274e-05"/>
      <axis xyz="-5.551115123125783e-17 1.2212453270876722e-15 0.9999999999999968"/>
      <limit lower="-0.4363323129985824" upper="0.6108652381980153" effort="100" velocity="100"/>
   </joint>
   <joint type="fixed" name="index_abd_offset">
      <parent link="index_abd_jointbody"/>
      <child link="index_um"/>
      <origin xyz="-0.014399999999999956 1.0278236595162582e-16 -1.431146867680866e-17" rpy="0.0 0.0 0.0"/>
   </joint>
   <link name="index_pp">
      <inertial>
         <origin xyz="0.0008687401920092231 -2.4862054760042404e-05 0.022247108199277357" rpy="-0.00113071384580111 -0.012433056943532472 0.0237556697838349"/>
         <mass value="0.006075709241757069"/>
         <inertia ixx="1.2759699630750096e-06" iyy="1.261715939586915e-06" izz="1.1563772656262221e-07" ixy="0" ixz="0" iyz="0"/>
      </inertial>
      <visual name="index_pp">
         <origin xyz="0.0008687401920092231 -2.4862054760042404e-05 0.022247108199277357" rpy="-0.0011307138458011082 -0.012433056943532472 0.0237556697838349"/>
         <geometry>
            <mesh filename="package://viz/models/orca1_hand/urdf/converted_index_pp.stl"/>
         </geometry>
         <material name="white"/>
      </visual>
   </link>
   <link name="root2index_pp_jointbody">
      <inertial>
         <origin xyz="0.0 0.0 0.0" rpy="0.0 0.0 0.0"/>
         <mass value="0.001"/>
         <inertia ixx="1e-09" iyy="1e-09" izz="1e-09" ixy="0" ixz="0" iyz="0"/>
      </inertial>
   </link>
   <joint type="revolute" name="root2index_pp">
      <parent link="index_um"/>
      <child link="root2index_pp_jointbody"/>
      <origin xyz="-6.511929505797567e-17 -1.2884579059542108e-16 1.2330918261215923e-17" rpy="-3.14159265358971 -1.5689140977438238 3.141592653589709"/>
      <axis xyz="9.992007221626409e-16 -1.000000000000004 -1.0130785099704553e-15"/>
      <limit lower="-0.17453292519943295" upper="2.007128639793479" effort="100" velocity="100"/>
   </joint>
   <joint type="fixed" name="root2index_pp_offset">
      <parent link="root2index_pp_jointbody"/>
      <child link="index_pp"/>
      <origin xyz="-2.2103198581084714e-18 -7.053339437169385e-18 1.2080891234349761e-18" rpy="0.0 0.0 0.0"/>
   </joint>
   <link name="index_mp">
      <inertial>
         <origin xyz="0.0013909738898894978 0.00016387532873425497 0.014968668474816213" rpy="0.03291128493942308 -0.020555715782136996 1.1076943559460612"/>
         <mass value="0.003108373341414378"/>
         <inertia ixx="3.251881563114705e-07" iyy="3.238587171666197e-07" izz="4.895669014432085e-08" ixy="0" ixz="0" iyz="0"/>
      </inertial>
      <visual name="index_mp">
         <origin xyz="0.0013909738898894978 0.00016387532873425497 0.014968668474816213" rpy="0.03291128493942308 -0.020555715782136774 1.107694355946061"/>
         <geometry>
            <mesh filename="package://viz/models/orca1_hand/urdf/converted_index_mp.stl"/>
         </geometry>
         <material name="white"/>
      </visual>
   </link>
   <link name="index_pp2mp_jointbody">
      <inertial>
         <origin xyz="0.0 0.0 0.0" rpy="0.0 0.0 0.0"/>
         <mass value="0.001"/>
         <inertia ixx="1e-09" iyy="1e-09" izz="1e-09" ixy="0" ixz="0" iyz="0"/>
      </inertial>
   </link>
   <joint type="revolute" name="index_pp2mp">
      <parent link="index_pp"/>
      <child link="index_pp2mp_jointbody"/>
      <origin xyz="-3.5654192458018814e-17 -1.9773193420734087e-17 0.04000000000000007" rpy="-6.938893903907228e-17 2.220446049250313e-16 1.1102230246251565e-16"/>
      <axis xyz="8.326672684688674e-16 -0.9999999999999992 -9.506284648352903e-16"/>
      <limit lower="0.0" upper="2.0943951023931953" effort="100" velocity="100"/>
   </joint>
   <joint type="fixed" name="index_pp2mp_offset">
      <parent link="index_pp2mp_jointbody"/>
      <child link="index_mp"/>
      <origin xyz="1.722275552576525e-17 2.4110002110676104e-17 -3.2175644141916336e-17" rpy="0.0 0.0 0.0"/>
   </joint>
   <link name="index_dp">
      <inertial>
         <origin xyz="-1.3890187096631583e-05 0.005054400100332685 -0.00020300962240500135" rpy="1.4604505475177294 -0.03444883339617988 0.0022630734580013634"/>
         <mass value="0.0011385821737687244"/>
         <inertia ixx="5.751980191525933e-08" iyy="5.65392336466142e-08" izz="1.0221302805317223e-08" ixy="0" ixz="0" iyz="0"/>
      </inertial>
      <visual name="index_dp">
         <origin xyz="-1.3890187096631583e-05 0.005054400100332685 -0.00020300962240500135" rpy="1.4604505475177294 -0.03444883339617988 0.0022630734580013634"/>
         <geometry>
            <mesh filename="package://viz/models/orca1_hand/urdf/converted_index_dp.stl"/>
         </geometry>
         <material name="white"/>
      </visual>
   </link>
   <link name="index_mp2dp_jointbody">
      <inertial>
         <origin xyz="0.0 0.0 0.0" rpy="0.0 0.0 0.0"/>
         <mass value="0.001"/>
         <inertia ixx="1e-09" iyy="1e-09" izz="1e-09" ixy="0" ixz="0" iyz="0"/>
      </inertial>
   </link>
   <joint type="revolute" name="index_mp2dp">
      <parent link="index_mp"/>
      <child link="index_mp2dp_jointbody"/>
      <origin xyz="0.0009999999999999543 -8.177594885971917e-17 0.027999999999999962" rpy="1.570796326794896 1.1102230246251565e-15 1.5707963267948963"/>
      <axis xyz="-0.9999999999999996 -2.0261570199409107e-15 1.0547118733938987e-15"/>
      <limit lower="0.0" upper="1.3089969389957472" effort="100" velocity="100"/>
   </joint>
   <joint type="fixed" name="index_mp2dp_offset">
      <parent link="index_mp2dp_jointbody"/>
      <child link="index_dp"/>
      <origin xyz="-9.999999999994138e-05 5.371544138307871e-17 3.0201383250825706e-17" rpy="0.0 0.0 0.0"/>
   </joint>
   <link name="index_fingertip">
      <inertial>
         <origin xyz="0.0 0.02 -0.001306" rpy="0.0 0.0 0.0"/>
         <mass value="0.0"/>
         <inertia ixx="0.0" iyy="0.0" izz="0.0" ixy="0" ixz="0" iyz="0"/>
      </inertial>
   </link>
   <link name="index_dp2index_fingertip_fixed_jointbody">
      <inertial>
         <origin xyz="0.0 0.0 0.0" rpy="0.0 0.0 0.0"/>
         <mass value="0.001"/>
         <inertia ixx="1e-09" iyy="1e-09" izz="1e-09" ixy="0" ixz="0" iyz="0"/>
      </inertial>
   </link>
   <joint type="fixed" name="index_dp2index_fingertip_fixed">
      <parent link="index_dp"/>
      <child link="index_dp2index_fingertip_fixed_jointbody"/>
      <origin xyz="0.0 0.02 -0.001306" rpy="0.0 0.0 0.0"/>
   </joint>
   <joint type="fixed" name="index_dp2index_fingertip_fixed_offset">
      <parent link="index_dp2index_fingertip_fixed_jointbody"/>
      <child link="index_fingertip"/>
      <origin xyz="-0.0 -0.0 -0.0" rpy="0.0 0.0 0.0"/>
   </joint>
   <link name="pinky_um">
      <inertial>
         <origin xyz="0.006732763304155957 4.001088863436687e-09 -2.0258619702217643e-05" rpy="-3.131684616200393 -1.561854856603541 -0.009908433449917098"/>
         <mass value="0.002607186033198995"/>
         <inertia ixx="1.3807074528604164e-07" iyy="1.1778104249469416e-07" izz="6.49217043247213e-08" ixy="0" ixz="0" iyz="0"/>
      </inertial>
      <visual name="pinky_um">
         <origin xyz="0.006732763304155957 4.001088863436687e-09 -2.0258619702217643e-05" rpy="-3.131684616200393 -1.561854856603541 -0.009908433449916876"/>
         <geometry>
            <mesh filename="package://viz/models/orca1_hand/urdf/converted_pinky_um.stl"/>
         </geometry>
         <material name="white"/>
      </visual>
   </link>
   <link name="pinky_abd_jointbody">
      <inertial>
         <origin xyz="0.0 0.0 0.0" rpy="0.0 0.0 0.0"/>
         <mass value="0.001"/>
         <inertia ixx="1e-09" iyy="1e-09" izz="1e-09" ixy="0" ixz="0" iyz="0"/>
      </inertial>
   </link>
   <joint type="revolute" name="pinky_abd">
      <parent link="palm"/>
      <child link="pinky_abd_jointbody"/>
      <origin xyz="0.04123255613565277 0.005128234212297354 0.015805277968103645" rpy="-1.5799161189708797 0.9071946146015462 -2.8781819803477346"/>
      <axis xyz="-1.942890293094024e-16 6.661338147750939e-16 -1.0000000000000004"/>
      <limit lower="-0.6108652381980153" upper="0.4363323129985824" effort="100" velocity="100"/>
   </joint>
   <joint type="fixed" name="pinky_abd_offset">
      <parent link="pinky_abd_jointbody"/>
      <child link="pinky_um"/>
      <origin xyz="-0.014400000000000012 2.211772431870429e-17 -1.5178830414797062e-17" rpy="0.0 0.0 0.0"/>
   </joint>
   <link name="pinky_pp">
      <inertial>
         <origin xyz="0.0008258154520941577 -2.2222565756841063e-05 0.016729787379917885" rpy="-0.0012233283283072625 -0.019834837027373764 0.012268708074692703"/>
         <mass value="0.0046751560406718806"/>
         <inertia ixx="6.47008260669387e-07" iyy="6.357773713013815e-07" izz="9.004187327563991e-08" ixy="0" ixz="0" iyz="0"/>
      </inertial>
      <visual name="pinky_pp">
         <origin xyz="0.0008258154520941577 -2.2222565756841063e-05 0.016729787379917885" rpy="-0.0012233283283072625 -0.019834837027373764 0.012268708074692703"/>
         <geometry>
            <mesh filename="package://viz/models/orca1_hand/urdf/converted_pinky_pp.stl"/>
         </geometry>
         <material name="white"/>
      </visual>
   </link>
   <link name="root2pinky_pp_jointbody">
      <inertial>
         <origin xyz="0.0 0.0 0.0" rpy="0.0 0.0 0.0"/>
         <mass value="0.001"/>
         <inertia ixx="1e-09" iyy="1e-09" izz="1e-09" ixy="0" ixz="0" iyz="0"/>
      </inertial>
   </link>
   <joint type="revolute" name="root2pinky_pp">
      <parent link="pinky_um"/>
      <child link="root2pinky_pp_jointbody"/>
      <origin xyz="3.525016089636266e-17 -3.1056381288997515e-19 2.7390067716395695e-17" rpy="3.141592653589439 -1.5692446522906773 -3.141592653589439"/>
      <axis xyz="-3.885780586188048e-16 -1.0000000000000004 -2.636779683484747e-16"/>
      <limit lower="-0.17453292519943295" upper="2.007128639793479" effort="100" velocity="100"/>
   </joint>
   <joint type="fixed" name="root2pinky_pp_offset">
      <parent link="root2pinky_pp_jointbody"/>
      <child link="pinky_pp"/>
      <origin xyz="-3.833184058085544e-18 7.922763782835389e-18 1.4973823299787632e-17" rpy="0.0 0.0 0.0"/>
   </joint>
   <link name="pinky_mp">
      <inertial>
         <origin xyz="0.0013909738898894978 0.00016387532873425497 0.014968668474816213" rpy="0.03291128493942308 -0.020555715782136996 1.1076943559460612"/>
         <mass value="0.003108373341414378"/>
         <inertia ixx="3.251881563114705e-07" iyy="3.238587171666197e-07" izz="4.895669014432085e-08" ixy="0" ixz="0" iyz="0"/>
      </inertial>
      <visual name="pinky_mp">
         <origin xyz="0.0013909738898894978 0.00016387532873425497 0.014968668474816213" rpy="0.03291128493942308 -0.020555715782136774 1.107694355946061"/>
         <geometry>
            <mesh filename="package://viz/models/orca1_hand/urdf/converted_pinky_mp.stl"/>
         </geometry>
         <material name="white"/>
      </visual>
   </link>
   <link name="pinky_pp2mp_jointbody">
      <inertial>
         <origin xyz="0.0 0.0 0.0" rpy="0.0 0.0 0.0"/>
         <mass value="0.001"/>
         <inertia ixx="1e-09" iyy="1e-09" izz="1e-09" ixy="0" ixz="0" iyz="0"/>
      </inertial>
   </link>
   <joint type="revolute" name="pinky_pp2mp">
      <parent link="pinky_pp"/>
      <child link="pinky_pp2mp_jointbody"/>
      <origin xyz="-2.02538279309526e-17 -3.2474578016063654e-17 0.03000000000000008" rpy="-5.551115123125783e-17 0.0 0.0"/>
      <axis xyz="-4.440892098500626e-16 -1.0000000000000004 -8.326672684688674e-17"/>
      <limit lower="0.0" upper="2.0943951023931953" effort="100" velocity="100"/>
   </joint>
   <joint type="fixed" name="pinky_pp2mp_offset">
      <parent link="pinky_pp2mp_jointbody"/>
      <child link="pinky_mp"/>
      <origin xyz="1.171869695207721e-18 -8.725104538385514e-18 -2.4424879789821522e-17" rpy="0.0 0.0 0.0"/>
   </joint>
   <link name="pinky_dp">
      <inertial>
         <origin xyz="-1.3890187096631583e-05 0.005054400100332685 -0.00020300962240500135" rpy="1.4604505475177294 -0.03444883339617988 0.0022630734580013634"/>
         <mass value="0.0011385821737687244"/>
         <inertia ixx="5.751980191525933e-08" iyy="5.65392336466142e-08" izz="1.0221302805317223e-08" ixy="0" ixz="0" iyz="0"/>
      </inertial>
      <visual name="pinky_dp">
         <origin xyz="-1.3890187096631583e-05 0.005054400100332685 -0.00020300962240500135" rpy="1.4604505475177294 -0.03444883339617988 0.0022630734580013634"/>
         <geometry>
            <mesh filename="package://viz/models/orca1_hand/urdf/converted_pinky_dp.stl"/>
         </geometry>
         <material name="white"/>
      </visual>
   </link>
   <link name="pinky_mp2dp_jointbody">
      <inertial>
         <origin xyz="0.0 0.0 0.0" rpy="0.0 0.0 0.0"/>
         <mass value="0.001"/>
         <inertia ixx="1e-09" iyy="1e-09" izz="1e-09" ixy="0" ixz="0" iyz="0"/>
      </inertial>
   </link>
   <joint type="revolute" name="pinky_mp2dp">
      <parent link="pinky_mp"/>
      <child link="pinky_mp2dp_jointbody"/>
      <origin xyz="0.0009999999999999842 6.46455545344482e-18 0.028000000000000067" rpy="1.570796326794896 4.440892098500626e-16 1.5707963267948968"/>
      <axis xyz="-1.0000000000000002 -3.0531133177191805e-16 -7.355227538141662e-16"/>
      <limit lower="0.0" upper="1.3089969389957472" effort="100" velocity="100"/>
   </joint>
   <joint type="fixed" name="pinky_mp2dp_offset">
      <parent link="pinky_mp2dp_jointbody"/>
      <child link="pinky_dp"/>
      <origin xyz="-0.00010000000000001497 -7.207742161365743e-17 -2.9290399316053706e-18" rpy="0.0 0.0 0.0"/>
   </joint>
   <link name="pinky_fingertip">
      <inertial>
         <origin xyz="0.0 0.02 -0.001306" rpy="0.0 0.0 0.0"/>
         <mass value="0.0"/>
         <inertia ixx="0.0" iyy="0.0" izz="0.0" ixy="0" ixz="0" iyz="0"/>
      </inertial>
   </link>
   <link name="pinky_dp2pinky_fingertip_fixed_jointbody">
      <inertial>
         <origin xyz="0.0 0.0 0.0" rpy="0.0 0.0 0.0"/>
         <mass value="0.001"/>
         <inertia ixx="1e-09" iyy="1e-09" izz="1e-09" ixy="0" ixz="0" iyz="0"/>
      </inertial>
   </link>
   <joint type="fixed" name="pinky_dp2pinky_fingertip_fixed">
      <parent link="pinky_dp"/>
      <child link="pinky_dp2pinky_fingertip_fixed_jointbody"/>
      <origin xyz="0.0 0.02 -0.001306" rpy="0.0 0.0 0.0"/>
   </joint>
   <joint type="fixed" name="pinky_dp2pinky_fingertip_fixed_offset">
      <parent link="pinky_dp2pinky_fingertip_fixed_jointbody"/>
      <child link="pinky_fingertip"/>
      <origin xyz="-0.0 -0.0 -0.0" rpy="0.0 0.0 0.0"/>
   </joint>
   <link name="ring_um">
      <inertial>
         <origin xyz="0.006732763304155957 4.001088863436687e-09 -2.0258619702217643e-05" rpy="-3.131684616200393 -1.561854856603541 -0.009908433449917098"/>
         <mass value="0.002607186033198995"/>
         <inertia ixx="1.3807074528604164e-07" iyy="1.1778104249469416e-07" izz="6.49217043247213e-08" ixy="0" ixz="0" iyz="0"/>
      </inertial>
      <visual name="ring_um">
         <origin xyz="0.006732763304155957 4.001088863436687e-09 -2.0258619702217643e-05" rpy="-3.131684616200393 -1.561854856603541 -0.009908433449916876"/>
         <geometry>
            <mesh filename="package://viz/models/orca1_hand/urdf/converted_ring_um.stl"/>
         </geometry>
         <material name="white"/>
      </visual>
   </link>
   <link name="ring_abd_jointbody">
      <inertial>
         <origin xyz="0.0 0.0 0.0" rpy="0.0 0.0 0.0"/>
         <mass value="0.001"/>
         <inertia ixx="1e-09" iyy="1e-09" izz="1e-09" ixy="0" ixz="0" iyz="0"/>
      </inertial>
   </link>
   <joint type="revolute" name="ring_abd">
      <parent link="palm"/>
      <child link="ring_abd_jointbody"/>
      <origin xyz="0.019694864162417412 0.0013825982229840389 0.030586364349873878" rpy="-1.5707963267948921 1.3088618425821554 -3.054326190990074"/>
      <axis xyz="6.38378239159465e-16 7.771561172376096e-16 0.9999999999999978"/>
      <limit lower="-0.4363323129985824" upper="0.6108652381980153" effort="100" velocity="100"/>
   </joint>
   <joint type="fixed" name="ring_abd_offset">
      <parent link="ring_abd_jointbody"/>
      <child link="ring_um"/>
      <origin xyz="-0.014399999999999944 5.941427905220564e-17 1.5178830414797062e-17" rpy="0.0 0.0 0.0"/>
   </joint>
   <link name="ring_pp">
      <inertial>
         <origin xyz="0.0008879048431632835 -2.537949357785257e-05 0.026668810452510044" rpy="-0.0011314495857910837 -0.009859569454313544 0.029169093210231874"/>
         <mass value="0.007199054377400034"/>
         <inertia ixx="2.0187701497182777e-06" iyy="2.002065106814579e-06" izz="1.361803516902417e-07" ixy="0" ixz="0" iyz="0"/>
      </inertial>
      <visual name="ring_pp">
         <origin xyz="0.0008879048431632835 -2.537949357785257e-05 0.026668810452510044" rpy="-0.0011314495857910837 -0.009859569454313544 0.029169093210231874"/>
         <geometry>
            <mesh filename="package://viz/models/orca1_hand/urdf/converted_ring_pp.stl"/>
         </geometry>
         <material name="white"/>
      </visual>
   </link>
   <link name="root2ring_pp_jointbody">
      <inertial>
         <origin xyz="0.0 0.0 0.0" rpy="0.0 0.0 0.0"/>
         <mass value="0.001"/>
         <inertia ixx="1e-09" iyy="1e-09" izz="1e-09" ixy="0" ixz="0" iyz="0"/>
      </inertial>
   </link>
   <joint type="revolute" name="root2ring_pp">
      <parent link="ring_um"/>
      <child link="root2ring_pp_jointbody"/>
      <origin xyz="-8.061277083623726e-17 -2.084317473075087e-17 -8.48575991563069e-18" rpy="3.1415926535897474 -1.569095233503671 -3.1415926535897465"/>
      <axis xyz="-5.551115123125783e-17 -1.0000000000000022 1.7139067942650854e-15"/>
      <limit lower="-0.17453292519943295" upper="2.007128639793479" effort="100" velocity="100"/>
   </joint>
   <joint type="fixed" name="root2ring_pp_offset">
      <parent link="root2ring_pp_jointbody"/>
      <child link="ring_pp"/>
      <origin xyz="2.763004548120401e-19 6.477168015932836e-18 1.61034059853451e-17" rpy="0.0 0.0 0.0"/>
   </joint>
   <link name="ring_mp">
      <inertial>
         <origin xyz="0.0013909738898894978 0.00016387532873425497 0.014968668474816213" rpy="0.03291128493942308 -0.020555715782136996 1.1076943559460612"/>
         <mass value="0.003108373341414378"/>
         <inertia ixx="3.251881563114705e-07" iyy="3.238587171666197e-07" izz="4.895669014432085e-08" ixy="0" ixz="0" iyz="0"/>
      </inertial>
      <visual name="ring_mp">
         <origin xyz="0.0013909738898894978 0.00016387532873425497 0.014968668474816213" rpy="0.03291128493942308 -0.020555715782136774 1.107694355946061"/>
         <geometry>
            <mesh filename="package://viz/models/orca1_hand/urdf/converted_ring_mp.stl"/>
         </geometry>
         <material name="white"/>
      </visual>
   </link>
   <link name="ring_pp2mp_jointbody">
      <inertial>
         <origin xyz="0.0 0.0 0.0" rpy="0.0 0.0 0.0"/>
         <mass value="0.001"/>
         <inertia ixx="1e-09" iyy="1e-09" izz="1e-09" ixy="0" ixz="0" iyz="0"/>
      </inertial>
   </link>
   <joint type="revolute" name="ring_pp2mp">
      <parent link="ring_pp"/>
      <child link="ring_pp2mp_jointbody"/>
      <origin xyz="-8.020486901317957e-19 8.994390474632575e-17 0.04800000000000009" rpy="-2.465190328815662e-32 -4.440892098500626e-16 1.1102230246251565e-16"/>
      <axis xyz="-2.7755575615628914e-16 -0.9999999999999994 1.734723475976807e-15"/>
      <limit lower="0.0" upper="2.0943951023931953" effort="100" velocity="100"/>
   </joint>
   <joint type="fixed" name="ring_pp2mp_offset">
      <parent link="ring_pp2mp_jointbody"/>
      <child link="ring_mp"/>
      <origin xyz="-2.4785122580526127e-17 -9.905120299520399e-17 -1.2157278934836427e-17" rpy="0.0 0.0 0.0"/>
   </joint>
   <link name="ring_dp">
      <inertial>
         <origin xyz="-1.3890187096631583e-05 0.005054400100332685 -0.00020300962240500135" rpy="1.4604505475177294 -0.03444883339617988 0.0022630734580013634"/>
         <mass value="0.0011385821737687244"/>
         <inertia ixx="5.751980191525933e-08" iyy="5.65392336466142e-08" izz="1.0221302805317223e-08" ixy="0" ixz="0" iyz="0"/>
      </inertial>
      <visual name="ring_dp">
         <origin xyz="-1.3890187096631583e-05 0.005054400100332685 -0.00020300962240500135" rpy="1.4604505475177294 -0.03444883339617988 0.0022630734580013634"/>
         <geometry>
            <mesh filename="package://viz/models/orca1_hand/urdf/converted_ring_dp.stl"/>
         </geometry>
         <material name="white"/>
      </visual>
   </link>
   <link name="ring_mp2dp_jointbody">
      <inertial>
         <origin xyz="0.0 0.0 0.0" rpy="0.0 0.0 0.0"/>
         <mass value="0.001"/>
         <inertia ixx="1e-09" iyy="1e-09" izz="1e-09" ixy="0" ixz="0" iyz="0"/>
      </inertial>
   </link>
   <joint type="revolute" name="ring_mp2dp">
      <parent link="ring_mp"/>
      <child link="ring_mp2dp_jointbody"/>
      <origin xyz="0.0010000000000000406 1.4632114375292307e-16 0.028000000000000025" rpy="1.5707963267948963 2.6645352591003757e-15 1.5707963267948963"/>
      <axis xyz="-1.0000000000000004 -8.881784197001252e-16 9.020562075079397e-17"/>
      <limit lower="0.0" upper="1.3089969389957472" effort="100" velocity="100"/>
   </joint>
   <joint type="fixed" name="ring_mp2dp_offset">
      <parent link="ring_mp2dp_jointbody"/>
      <child link="ring_dp"/>
      <origin xyz="-1.3721384550404466e-16 -6.547177265705249e-17 -4.2773936368871135e-17" rpy="0.0 0.0 0.0"/>
   </joint>
   <link name="ring_fingertip">
      <inertial>
         <origin xyz="0.0 0.02 -0.001306" rpy="0.0 0.0 0.0"/>
         <mass value="0.0"/>
         <inertia ixx="0.0" iyy="0.0" izz="0.0" ixy="0" ixz="0" iyz="0"/>
      </inertial>
   </link>
   <link name="ring_dp2ring_fingertip_fixed_jointbody">
      <inertial>
         <origin xyz="0.0 0.0 0.0" rpy="0.0 0.0 0.0"/>
         <mass value="0.001"/>
         <inertia ixx="1e-09" iyy="1e-09" izz="1e-09" ixy="0" ixz="0" iyz="0"/>
      </inertial>
   </link>
   <joint type="fixed" name="ring_dp2ring_fingertip_fixed">
      <parent link="ring_dp"/>
      <child link="ring_dp2ring_fingertip_fixed_jointbody"/>
      <origin xyz="0.0 0.02 -0.001306" rpy="0.0 0.0 0.0"/>
   </joint>
   <joint type="fixed" name="ring_dp2ring_fingertip_fixed_offset">
      <parent link="ring_dp2ring_fingertip_fixed_jointbody"/>
      <child link="ring_fingertip"/>
      <origin xyz="-0.0 -0.0 -0.0" rpy="0.0 0.0 0.0"/>
   </joint>
   <link name="thumb_base">
      <inertial>
         <origin xyz="0.008808869187580644 6.0539790788424805e-05 -6.227108387365731e-07" rpy="1.5867431449904335 -1.5487623466463896 1.5779915757952099"/>
         <mass value="0.004343232157026885"/>
         <inertia ixx="3.2542026380799935e-07" iyy="2.8172270770847253e-07" izz="1.4637236276937704e-07" ixy="0" ixz="0" iyz="0"/>
      </inertial>
      <visual name="thumb_base">
         <origin xyz="0.008808869187580644 6.0539790788424805e-05 -6.227108387365731e-07" rpy="1.5867431449904335 -1.5487623466463896 1.5779915757952099"/>
         <geometry>
            <mesh filename="package://viz/models/orca1_hand/urdf/converted_thumb_base.stl"/>
         </geometry>
         <material name="white"/>
      </visual>
   </link>
   <link name="root2thumb_base_jointbody">
      <inertial>
         <origin xyz="0.0 0.0 0.0" rpy="0.0 0.0 0.0"/>
         <mass value="0.001"/>
         <inertia ixx="1e-09" iyy="1e-09" izz="1e-09" ixy="0" ixz="0" iyz="0"/>
      </inertial>
   </link>
   <joint type="revolute" name="root2thumb_base">
      <parent link="palm"/>
      <child link="root2thumb_base_jointbody"/>
      <origin xyz="-0.01933668556029309 0.007354881795979843 -0.02738447811197526" rpy="-2.2765234291633645 0.5077476451224663 -0.8026267442856543"/>
      <axis xyz="1.1657341758564144e-15 -2.220446049250313e-15 -0.9999999999999962"/>
      <limit lower="-1.3089969389957472" upper="1.3089969389957472" effort="100" velocity="100"/>
   </joint>
   <joint type="fixed" name="root2thumb_base_offset">
      <parent link="root2thumb_base_jointbody"/>
      <child link="thumb_base"/>
      <origin xyz="-0.016900000000000366 -6.505213034913027e-17 -1.8106176280507924e-16" rpy="0.0 0.0 0.0"/>
   </joint>
   <link name="thumb_pp">
      <inertial>
         <origin xyz="0.0110035065603882 1.2140320581283004e-05 4.99089698308662e-06" rpy="1.5801938322395839 -1.3458483295749617 1.5649015598749747"/>
         <mass value="0.005082655147362075"/>
         <inertia ixx="5.315792864935883e-07" iyy="4.848428109529283e-07" izz="1.5884694021631092e-07" ixy="0" ixz="0" iyz="0"/>
      </inertial>
      <visual name="thumb_pp">
         <origin xyz="0.0110035065603882 1.2140320581283004e-05 4.99089698308662e-06" rpy="1.5801938322395845 -1.3458483295749617 1.564901559874974"/>
         <geometry>
            <mesh filename="package://viz/models/orca1_hand/urdf/converted_thumb_pp.stl"/>
         </geometry>
         <material name="white"/>
      </visual>
   </link>
   <link name="thumb_base2pp_jointbody">
      <inertial>
         <origin xyz="0.0 0.0 0.0" rpy="0.0 0.0 0.0"/>
         <mass value="0.001"/>
         <inertia ixx="1e-09" iyy="1e-09" izz="1e-09" ixy="0" ixz="0" iyz="0"/>
      </inertial>
   </link>
   <joint type="revolute" name="thumb_base2pp">
      <parent link="thumb_base"/>
      <child link="thumb_base2pp_jointbody"/>
      <origin xyz="6.696032617270475e-16 1.8030049447620726e-16 1.04077532652539e-16" rpy="2.0071286397934847 -2.4424906541753444e-15 -1.5543122344752192e-15"/>
      <axis xyz="1.0824674490095276e-15 -0.42261826174070033 -0.9063077870366472"/>
      <limit lower="-0.7853981633974483" upper="0.7853981633974483" effort="100" velocity="100"/>
   </joint>
   <joint type="fixed" name="thumb_base2pp_offset">
      <parent link="thumb_base2pp_jointbody"/>
      <child link="thumb_pp"/>
      <origin xyz="-0.023000000000001172 -9.367506770274758e-17 -3.499533562240087e-16" rpy="0.0 0.0 0.0"/>
   </joint>
   <link name="thumb_mp">
      <inertial>
         <origin xyz="0.0008671837157415993 3.6807067201715006e-05 0.014545771273496376" rpy="0.00077585773810393 -0.01657317387693391 0.012834020797146971"/>
         <mass value="0.004591034960824554"/>
         <inertia ixx="5.918485249131172e-07" iyy="5.836019355467322e-07" izz="9.196006074468986e-08" ixy="0" ixz="0" iyz="0"/>
      </inertial>
      <visual name="thumb_mp">
         <origin xyz="0.0008671837157415993 3.6807067201715006e-05 0.014545771273496376" rpy="0.00077585773810393 -0.01657317387693391 0.012834020797146971"/>
         <geometry>
            <mesh filename="package://viz/models/orca1_hand/urdf/converted_thumb_mp.stl"/>
         </geometry>
         <material name="white"/>
      </visual>
   </link>
   <link name="thumb_pp2mp_jointbody">
      <inertial>
         <origin xyz="0.0 0.0 0.0" rpy="0.0 0.0 0.0"/>
         <mass value="0.001"/>
         <inertia ixx="1e-09" iyy="1e-09" izz="1e-09" ixy="0" ixz="0" iyz="0"/>
      </inertial>
   </link>
   <joint type="revolute" name="thumb_pp2mp">
      <parent link="thumb_pp"/>
      <child link="thumb_pp2mp_jointbody"/>
      <origin xyz="1.0061975309744072e-15 1.5763860490676992e-16 6.475155218103694e-16" rpy="3.1415926535897905 1.5707963267948797 0.0"/>
      <axis xyz="-6.8833827526759706e-15 -0.9999999999999959 -7.993605777301127e-15"/>
      <limit lower="-0.17453292519943295" upper="1.5707963267948966" effort="100" velocity="100"/>
   </joint>
   <joint type="fixed" name="thumb_pp2mp_offset">
      <parent link="thumb_pp2mp_jointbody"/>
      <child link="thumb_mp"/>
      <origin xyz="-6.8988979146713415e-18 -2.155793885708645e-17 -2.0127088287987651e-16" rpy="0.0 0.0 0.0"/>
   </joint>
   <link name="thumb_dp">
      <inertial>
         <origin xyz="1.0065826614441387e-05 0.006272335517680365 -0.00010113404865312324" rpy="1.4779757020900604 0.03179381852807506 -0.0019765844728094617"/>
         <mass value="0.001814128231283667"/>
         <inertia ixx="1.4115416029381981e-07" iyy="1.3962326809815754e-07" izz="2.257709422103513e-08" ixy="0" ixz="0" iyz="0"/>
      </inertial>
      <visual name="thumb_dp">
         <origin xyz="1.0065826614441387e-05 0.006272335517680365 -0.00010113404865312324" rpy="1.4779757020900601 0.03179381852807506 -0.0019765844728094617"/>
         <geometry>
            <mesh filename="package://viz/models/orca1_hand/urdf/converted_thumb_dp.stl"/>
         </geometry>
         <material name="white"/>
      </visual>
   </link>
   <link name="thumb_mp2dp_jointbody">
      <inertial>
         <origin xyz="0.0 0.0 0.0" rpy="0.0 0.0 0.0"/>
         <mass value="0.001"/>
         <inertia ixx="1e-09" iyy="1e-09" izz="1e-09" ixy="0" ixz="0" iyz="0"/>
      </inertial>
   </link>
   <joint type="revolute" name="thumb_mp2dp">
      <parent link="thumb_mp"/>
      <child link="thumb_mp2dp_jointbody"/>
      <origin xyz="1.239088163743751e-16 5.408958416957225e-16 0.03000000000000005" rpy="1.5707963267949039 -8.659739592076221e-15 1.570796326794891"/>
      <axis xyz="0.9999999999999958 -9.992007221626409e-16 1.7486012637846216e-15"/>
      <limit lower="-1.7453292519943295" upper="0.0" effort="100" velocity="100"/>
   </joint>
   <joint type="fixed" name="thumb_mp2dp_offset">
      <parent link="thumb_mp2dp_jointbody"/>
      <child link="thumb_dp"/>
      <origin xyz="-6.3846885802101e-17 -2.638575629691531e-17 -2.8715865630147274e-17" rpy="0.0 0.0 0.0"/>
   </joint>
   <link name="thumb_fingertip">
      <inertial>
         <origin xyz="0.0 0.02425 -0.001189" rpy="0.0 0.0 0.0"/>
         <mass value="0.0"/>
         <inertia ixx="0.0" iyy="0.0" izz="0.0" ixy="0" ixz="0" iyz="0"/>
      </inertial>
   </link>
   <link name="thumb_dp2thumb_fingertip_fixed_jointbody">
      <inertial>
         <origin xyz="0.0 0.0 0.0" rpy="0.0 0.0 0.0"/>
         <mass value="0.001"/>
         <inertia ixx="1e-09" iyy="1e-09" izz="1e-09" ixy="0" ixz="0" iyz="0"/>
      </inertial>
   </link>
   <joint type="fixed" name="thumb_dp2thumb_fingertip_fixed">
      <parent link="thumb_dp"/>
      <child link="thumb_dp2thumb_fingertip_fixed_jointbody"/>
      <origin xyz="0.0 0.02425 -0.001189" rpy="0.0 0.0 0.0"/>
   </joint>
   <joint type="fixed" name="thumb_dp2thumb_fingertip_fixed_offset">
      <parent link="thumb_dp2thumb_fingertip_fixed_jointbody"/>
      <child link="thumb_fingertip"/>
      <origin xyz="-0.0 -0.0 -0.0" rpy="0.0 0.0 0.0"/>
   </joint>
   <link name="middle_um">
      <inertial>
         <origin xyz="0.006732763304155957 4.001088863436687e-09 -2.0258619702217643e-05" rpy="-3.131684616200393 -1.561854856603541 -0.009908433449917098"/>
         <mass value="0.002607186033198995"/>
         <inertia ixx="1.3807074528604164e-07" iyy="1.1778104249469416e-07" izz="6.49217043247213e-08" ixy="0" ixz="0" iyz="0"/>
      </inertial>
      <visual name="middle_um">
         <origin xyz="0.006732763304155957 4.001088863436687e-09 -2.0258619702217643e-05" rpy="-3.131684616200393 -1.561854856603541 -0.009908433449916876"/>
         <geometry>
            <mesh filename="package://viz/models/orca1_hand/urdf/converted_middle_um.stl"/>
         </geometry>
         <material name="white"/>
      </visual>
   </link>
   <link name="middle_abd_jointbody">
      <inertial>
         <origin xyz="0.0 0.0 0.0" rpy="0.0 0.0 0.0"/>
         <mass value="0.001"/>
         <inertia ixx="1e-09" iyy="1e-09" izz="1e-09" ixy="0" ixz="0" iyz="0"/>
      </inertial>
   </link>
   <joint type="revolute" name="middle_abd">
      <parent link="palm"/>
      <child link="middle_abd_jointbody"/>
      <origin xyz="-0.0009621394664390548 2.7740667835757045e-18 0.03895854381555531" rpy="1.5707963267948966 1.5707963267948948 0.0"/>
      <axis xyz="1.3877787807814457e-15 1.1102230246251565e-16 0.9999999999999987"/>
      <limit lower="-0.4363323129985824" upper="0.6108652381980153" effort="100" velocity="100"/>
   </joint>
   <joint type="fixed" name="middle_abd_offset">
      <parent link="middle_abd_jointbody"/>
      <child link="middle_um"/>
      <origin xyz="-0.014400000000000015 -2.0816681711721685e-17 2.0383000842727483e-17" rpy="0.0 0.0 0.0"/>
   </joint>
   <link name="middle_pp">
      <inertial>
         <origin xyz="0.0008879048431632835 -2.537949357785257e-05 0.026668810452510044" rpy="-0.0011314495857910837 -0.009859569454313544 0.029169093210231874"/>
         <mass value="0.007199054377400034"/>
         <inertia ixx="2.0187701497182777e-06" iyy="2.002065106814579e-06" izz="1.361803516902417e-07" ixy="0" ixz="0" iyz="0"/>
      </inertial>
      <visual name="middle_pp">
         <origin xyz="0.0008879048431632835 -2.537949357785257e-05 0.026668810452510044" rpy="-0.0011314495857910837 -0.009859569454313544 0.029169093210231874"/>
         <geometry>
            <mesh filename="package://viz/models/orca1_hand/urdf/converted_middle_pp.stl"/>
         </geometry>
         <material name="white"/>
      </visual>
   </link>
   <link name="root2middle_pp_jointbody">
      <inertial>
         <origin xyz="0.0 0.0 0.0" rpy="0.0 0.0 0.0"/>
         <mass value="0.001"/>
         <inertia ixx="1e-09" iyy="1e-09" izz="1e-09" ixy="0" ixz="0" iyz="0"/>
      </inertial>
   </link>
   <joint type="revolute" name="root2middle_pp">
      <parent link="middle_um"/>
      <child link="root2middle_pp_jointbody"/>
      <origin xyz="-2.7755588056615305e-17 2.7755575615628864e-17 6.638549052222253e-21" rpy="3.141592653589793 -1.5689702811526907 3.141592653589793"/>
      <axis xyz="-1.1102230246251565e-16 -1.0000000000000009 9.75781955236954e-18"/>
      <limit lower="-0.17453292519943295" upper="2.007128639793479" effort="100" velocity="100"/>
   </joint>
   <joint type="fixed" name="root2middle_pp_offset">
      <parent link="root2middle_pp_jointbody"/>
      <child link="middle_pp"/>
      <origin xyz="1.5108221092759517e-20 -9.7018720948507e-33 1.3877779583938463e-17" rpy="0.0 0.0 0.0"/>
   </joint>
   <link name="middle_mp">
      <inertial>
         <origin xyz="0.0013909738898894978 0.00016387532873425497 0.014968668474816213" rpy="0.03291128493942308 -0.020555715782136996 1.1076943559460612"/>
         <mass value="0.003108373341414378"/>
         <inertia ixx="3.251881563114705e-07" iyy="3.238587171666197e-07" izz="4.895669014432085e-08" ixy="0" ixz="0" iyz="0"/>
      </inertial>
      <visual name="middle_mp">
         <origin xyz="0.0013909738898894978 0.00016387532873425497 0.014968668474816213" rpy="0.03291128493942308 -0.020555715782136774 1.107694355946061"/>
         <geometry>
            <mesh filename="package://viz/models/orca1_hand/urdf/converted_middle_mp.stl"/>
         </geometry>
         <material name="white"/>
      </visual>
   </link>
   <link name="middle_pp2mp_jointbody">
      <inertial>
         <origin xyz="0.0 0.0 0.0" rpy="0.0 0.0 0.0"/>
         <mass value="0.001"/>
         <inertia ixx="1e-09" iyy="1e-09" izz="1e-09" ixy="0" ixz="0" iyz="0"/>
      </inertial>
   </link>
   <joint type="revolute" name="middle_pp2mp">
      <parent link="middle_pp"/>
      <child link="middle_pp2mp_jointbody"/>
      <origin xyz="-1.8151956462261382e-17 -2.3920210430460702e-18 0.048000000000000154" rpy="6.114900252818245e-17 0.0 0.0"/>
      <axis xyz="-1.6653345369377348e-16 -1.0000000000000004 9.75781955236954e-18"/>
      <limit lower="0.0" upper="2.0943951023931953" effort="100" velocity="100"/>
   </joint>
   <joint type="fixed" name="middle_pp2mp_offset">
      <parent link="middle_pp2mp_jointbody"/>
      <child link="middle_mp"/>
      <origin xyz="-6.817933558779142e-17 -6.938893903907302e-18 7.4224300060933e-20" rpy="0.0 0.0 0.0"/>
   </joint>
   <link name="middle_dp">
      <inertial>
         <origin xyz="-1.3890187096631583e-05 0.005054400100332685 -0.00020300962240500135" rpy="1.4604505475177294 -0.03444883339617988 0.0022630734580013634"/>
         <mass value="0.0011385821737687244"/>
         <inertia ixx="5.751980191525933e-08" iyy="5.65392336466142e-08" izz="1.0221302805317223e-08" ixy="0" ixz="0" iyz="0"/>
      </inertial>
      <visual name="middle_dp">
         <origin xyz="-1.3890187096631583e-05 0.005054400100332685 -0.00020300962240500135" rpy="1.4604505475177294 -0.03444883339617988 0.0022630734580013634"/>
         <geometry>
            <mesh filename="package://viz/models/orca1_hand/urdf/converted_middle_dp.stl"/>
         </geometry>
         <material name="white"/>
      </visual>
   </link>
   <link name="middle_mp2dp_jointbody">
      <inertial>
         <origin xyz="0.0 0.0 0.0" rpy="0.0 0.0 0.0"/>
         <mass value="0.001"/>
         <inertia ixx="1e-09" iyy="1e-09" izz="1e-09" ixy="0" ixz="0" iyz="0"/>
      </inertial>
   </link>
   <joint type="revolute" name="middle_mp2dp">
      <parent link="middle_mp"/>
      <child link="middle_mp2dp_jointbody"/>
      <origin xyz="0.0010000000000000631 9.161508357502633e-18 0.028000000000000025" rpy="1.5707963267948948 0.0 1.5707963267948966"/>
      <axis xyz="-0.9999999999999994 1.159735553967606e-16 6.744138602805412e-17"/>
      <limit lower="0.0" upper="1.3089969389957472" effort="100" velocity="100"/>
   </joint>
   <joint type="fixed" name="middle_mp2dp_offset">
      <parent link="middle_mp2dp_jointbody"/>
      <child link="middle_dp"/>
      <origin xyz="-1.5612511283791412e-17 1.3361333028928368e-19 -1.2273161319545561e-16" rpy="0.0 0.0 0.0"/>
   </joint>
   <link name="middle_fingertip">
      <inertial>
         <origin xyz="0.0 0.02 -0.001306" rpy="0.0 0.0 0.0"/>
         <mass value="0.0"/>
         <inertia ixx="0.0" iyy="0.0" izz="0.0" ixy="0" ixz="0" iyz="0"/>
      </inertial>
   </link>
   <link name="middle_dp2middle_fingertip_fixed_jointbody">
      <inertial>
         <origin xyz="0.0 0.0 0.0" rpy="0.0 0.0 0.0"/>
         <mass value="0.001"/>
         <inertia ixx="1e-09" iyy="1e-09" izz="1e-09" ixy="0" ixz="0" iyz="0"/>
      </inertial>
   </link>
   <joint type="fixed" name="middle_dp2middle_fingertip_fixed">
      <parent link="middle_dp"/>
      <child link="middle_dp2middle_fingertip_fixed_jointbody"/>
      <origin xyz="0.0 0.02 -0.001306" rpy="0.0 0.0 0.0"/>
   </joint>
   <joint type="fixed" name="middle_dp2middle_fingertip_fixed_offset">
      <parent link="middle_dp2middle_fingertip_fixed_jointbody"/>
      <child link="middle_fingertip"/>
      <origin xyz="-0.0 -0.0 -0.0" rpy="0.0 0.0 0.0"/>
   </joint>
   <material name="white">
      <color rgba="1 1 1 1"/>
   </material>
</robot>
