<?xml version="1.0" ?>
<robot name="converted_robot">
   <link name="hand_root">
      <inertial>
         <origin xyz="0.0 0.0 0.0" rpy="0.0 0.0 0.0"/>
         <mass value="0.0"/>
         <inertia ixx="0.0" iyy="0.0" izz="0.0" ixy="0" ixz="0" iyz="0"/>
      </inertial>
   </link>
   <link name="palm">
      <inertial>
         <origin xyz="0.0031931161538907675 -0.0006744956817974197 -0.015141641629351442" rpy="0.11369803949052038 0.0015109688649919129 1.5487764199118472"/>
         <mass value="0.15922386065672636"/>
         <inertia ixx="0.00012041487596921829" iyy="8.59196043876551e-05" izz="4.1572032560976865e-05" ixy="0" ixz="0" iyz="0"/>
      </inertial>
      <visual name="palm_tower">
         <origin xyz="0.0031931161538907675 -0.0006744956817974197 -0.015141641629351442" rpy="0.11369803949052038 0.001510968864992135 1.5487764199118472"/>
         <geometry>
            <mesh filename="package://viz/models/orca1_hand/urdf/converted_palm_tower.stl"/>
         </geometry>
         <material name="white"/>
      </visual>
   </link>
   <link name="root2palm_fixed_jointbody">
      <inertial>
         <origin xyz="0.0 0.0 0.0" rpy="0.0 0.0 0.0"/>
         <mass value="0.001"/>
         <inertia ixx="1e-09" iyy="1e-09" izz="1e-09" ixy="0" ixz="0" iyz="0"/>
      </inertial>
   </link>
   <joint type="fixed" name="root2palm_fixed">
      <parent link="hand_root"/>
      <child link="root2palm_fixed_jointbody"/>
      <origin xyz="0.193999986406645 -3.686916491009634e-05 0.00199999999999996" rpy="0.0007373833650254783 1.5707963267948966 0.0"/>
   </joint>
   <joint type="fixed" name="root2palm_fixed_offset">
      <parent link="root2palm_fixed_jointbody"/>
      <child link="palm"/>
      <origin xyz="-0.0 -0.0 -0.0" rpy="0.0 0.0 0.0"/>
   </joint>
   <link name="index_um">
      <inertial>
         <origin xyz="0.006732763304155957 4.001088863436687e-09 -2.0258619702217643e-05" rpy="-3.131684616200393 -1.561854856603541 -0.009908433449917098"/>
         <mass value="0.002607186033198995"/>
         <inertia ixx="1.3807074528604164e-07" iyy="1.1778104249469416e-07" izz="6.49217043247213e-08" ixy="0" ixz="0" iyz="0"/>
      </inertial>
      <visual name="index_um">
         <origin xyz="0.006732763304155957 4.001088863436687e-09 -2.0258619702217643e-05" rpy="-3.131684616200393 -1.561854856603541 -0.009908433449916876"/>
         <geometry>
            <mesh filename="package://viz/models/orca1_hand/urdf/converted_index_um.stl"/>
         </geometry>
         <material name="white"/>
      </visual>
   </link>
   <link name="index_abd_jointbody">
      <inertial>
         <origin xyz="0.0 0.0 0.0" rpy="0.0 0.0 0.0"/>
         <mass value="0.001"/>
         <inertia ixx="1e-09" iyy="1e-09" izz="1e-09" ixy="0" ixz="0" iyz="0"/>
      </inertial>
   </link>
   <joint type="revolute" name="index_abd">
      <parent link="palm"/>
      <child link="index_abd_jointbody"/>
      <origin xyz="-0.022026898291690793 0.0015684105070722376 0.035558225043043304" rpy="1.657989451174792 1.3961154673834115 -7.447055134812697e-05"/>
      <axis xyz="-1.80855330711438e-13 -2.220446049250313e-16 0.9999999999999967"/>
      <limit lower="-0.4363323129985824" upper="0.6108652381980153" effort="100" velocity="100"/>
   </joint>
   <joint type="fixed" name="index_abd_offset">
      <parent link="index_abd_jointbody"/>
      <child link="index_um"/>
      <origin xyz="-0.014399999999999979 -1.1275702593849246e-17 -4.7704895589362195e-18" rpy="0.0 0.0 0.0"/>
   </joint>
   <link name="index_pp">
      <inertial>
         <origin xyz="0.001028909009164022 -4.063769783948308e-06 0.02054690935172239" rpy="0.0004528001968630863 -0.017765403380045175 -0.030452017041297512"/>
         <mass value="0.01253208205763138"/>
         <inertia ixx="1.693790150208706e-06" iyy="1.687388366681519e-06" izz="3.6847130608302664e-07" ixy="0" ixz="0" iyz="0"/>
      </inertial>
      <visual name="index_pp">
         <origin xyz="0.001028909009164022 -4.063769783948308e-06 0.02054690935172239" rpy="0.0004528001968630863 -0.017765403380045175 -0.03045201704129752"/>
         <geometry>
            <mesh filename="package://viz/models/orca1_hand/urdf/converted_index_pp.stl"/>
         </geometry>
         <material name="white"/>
      </visual>
   </link>
   <link name="root2index_pp_jointbody">
      <inertial>
         <origin xyz="0.0 0.0 0.0" rpy="0.0 0.0 0.0"/>
         <mass value="0.001"/>
         <inertia ixx="1e-09" iyy="1e-09" izz="1e-09" ixy="0" ixz="0" iyz="0"/>
      </inertial>
   </link>
   <joint type="revolute" name="root2index_pp">
      <parent link="index_um"/>
      <child link="root2index_pp_jointbody"/>
      <origin xyz="-3.726525911802163e-14 1.5826592868386048e-13 -1.3897728001093473e-14" rpy="3.141592653571369 -1.568914097743692 -3.1415926535734324"/>
      <axis xyz="3.175237850427948e-14 -1.0000000000000018 -2.0646956366832114e-12"/>
      <limit lower="-0.17453292519943295" upper="2.007128639793479" effort="100" velocity="100"/>
   </joint>
   <joint type="fixed" name="root2index_pp_offset">
      <parent link="root2index_pp_jointbody"/>
      <child link="index_pp"/>
      <origin xyz="9.357535447968366e-19 9.360525909273759e-18 1.2460153634354755e-17" rpy="0.0 0.0 0.0"/>
   </joint>
   <link name="index_mp">
      <inertial>
         <origin xyz="0.0014457760100068154 8.307526209729058e-05 0.014984285891448386" rpy="0.030434030316509056 -0.009961283507679886 0.10995570955517174"/>
         <mass value="0.007256911934241935"/>
         <inertia ixx="4.939234421836949e-07" iyy="4.903790475873879e-07" izz="1.9645010163470517e-07" ixy="0" ixz="0" iyz="0"/>
      </inertial>
      <visual name="index_mp">
         <origin xyz="0.0014457760100068154 8.307526209729058e-05 0.014984285891448386" rpy="0.030434030316509056 -0.009961283507679886 0.10995570955517174"/>
         <geometry>
            <mesh filename="package://viz/models/orca1_hand/urdf/converted_index_mp.stl"/>
         </geometry>
         <material name="white"/>
      </visual>
   </link>
   <link name="index_pp2mp_jointbody">
      <inertial>
         <origin xyz="0.0 0.0 0.0" rpy="0.0 0.0 0.0"/>
         <mass value="0.001"/>
         <inertia ixx="1e-09" iyy="1e-09" izz="1e-09" ixy="0" ixz="0" iyz="0"/>
      </inertial>
   </link>
   <joint type="revolute" name="index_pp2mp">
      <parent link="index_pp"/>
      <child link="index_pp2mp_jointbody"/>
      <origin xyz="-4.092895317840004e-17 -2.263553056912248e-17 0.039999999999999904" rpy="-1.387778780781445e-17 -2.220446049250313e-16 2.311115933264683e-33"/>
      <axis xyz="1.0547118733938987e-15 -0.9999999999999989 -9.020562075079397e-16"/>
      <limit lower="0.0" upper="2.0943951023931953" effort="100" velocity="100"/>
   </joint>
   <joint type="fixed" name="index_pp2mp_offset">
      <parent link="index_pp2mp_jointbody"/>
      <child link="index_mp"/>
      <origin xyz="1.9461750163187066e-17 3.195966925249782e-17 5.1027793401258624e-17" rpy="0.0 0.0 0.0"/>
   </joint>
   <link name="index_dp">
      <inertial>
         <origin xyz="0.010962775970379684 -0.0009207287499492076 0.007029609248376971" rpy="0.0038044439296488486 0.009595151767842092 1.742992635465892"/>
         <mass value="0.009142007854382036"/>
         <inertia ixx="7.030009842186787e-07" iyy="6.96709959144247e-07" izz="2.9942656232517023e-07" ixy="0" ixz="0" iyz="0"/>
      </inertial>
      <visual name="index_dp">
         <origin xyz="0.010962775970379684 -0.0009207287499492076 0.007029609248376971" rpy="0.0038044439296489596 0.009595151767842092 1.7429926354658922"/>
         <geometry>
            <mesh filename="package://viz/models/orca1_hand/urdf/converted_index_dp.stl"/>
         </geometry>
         <material name="white"/>
      </visual>
   </link>
   <link name="index_mp2dp_jointbody">
      <inertial>
         <origin xyz="0.0 0.0 0.0" rpy="0.0 0.0 0.0"/>
         <mass value="0.001"/>
         <inertia ixx="1e-09" iyy="1e-09" izz="1e-09" ixy="0" ixz="0" iyz="0"/>
      </inertial>
   </link>
   <joint type="revolute" name="index_mp2dp">
      <parent link="index_mp"/>
      <child link="index_mp2dp_jointbody"/>
      <origin xyz="0.0009999999999999601 -4.683753385137379e-17 0.028000000000000004" rpy="-6.661338147750939e-16 8.881784197001252e-16 1.5707963267948974"/>
      <axis xyz="-0.9999999999999998 -1.1796119636642288e-16 -1.946657895643411e-15"/>
      <limit lower="0.0" upper="1.3089969389957472" effort="100" velocity="100"/>
   </joint>
   <joint type="fixed" name="index_mp2dp_offset">
      <parent link="index_mp2dp_jointbody"/>
      <child link="index_dp"/>
      <origin xyz="-0.01099999999999995 7.281470469246501e-06 0.009007281470469294" rpy="0.0 0.0 0.0"/>
   </joint>
   <link name="index_fingertip">
      <inertial>
         <origin xyz="0.011 0.0 0.022" rpy="0.0 0.0 0.0"/>
         <mass value="0.0"/>
         <inertia ixx="0.0" iyy="0.0" izz="0.0" ixy="0" ixz="0" iyz="0"/>
      </inertial>
   </link>
   <link name="index_dp2index_fingertip_fixed_jointbody">
      <inertial>
         <origin xyz="0.0 0.0 0.0" rpy="0.0 0.0 0.0"/>
         <mass value="0.001"/>
         <inertia ixx="1e-09" iyy="1e-09" izz="1e-09" ixy="0" ixz="0" iyz="0"/>
      </inertial>
   </link>
   <joint type="fixed" name="index_dp2index_fingertip_fixed">
      <parent link="index_dp"/>
      <child link="index_dp2index_fingertip_fixed_jointbody"/>
      <origin xyz="0.011 0.0 0.022" rpy="0.0 0.0 0.0"/>
   </joint>
   <joint type="fixed" name="index_dp2index_fingertip_fixed_offset">
      <parent link="index_dp2index_fingertip_fixed_jointbody"/>
      <child link="index_fingertip"/>
      <origin xyz="-0.0 -0.0 -0.0" rpy="0.0 0.0 0.0"/>
   </joint>
   <link name="pinky_um">
      <inertial>
         <origin xyz="0.006732763304155957 4.001088863436687e-09 -2.0258619702217643e-05" rpy="-3.131684616200393 -1.561854856603541 -0.009908433449917098"/>
         <mass value="0.002607186033198995"/>
         <inertia ixx="1.3807074528604164e-07" iyy="1.1778104249469416e-07" izz="6.49217043247213e-08" ixy="0" ixz="0" iyz="0"/>
      </inertial>
      <visual name="pinky_um">
         <origin xyz="0.006732763304155957 4.001088863436687e-09 -2.0258619702217643e-05" rpy="-3.131684616200393 -1.561854856603541 -0.009908433449916876"/>
         <geometry>
            <mesh filename="package://viz/models/orca1_hand/urdf/converted_pinky_um.stl"/>
         </geometry>
         <material name="white"/>
      </visual>
   </link>
   <link name="pinky_abd_jointbody">
      <inertial>
         <origin xyz="0.0 0.0 0.0" rpy="0.0 0.0 0.0"/>
         <mass value="0.001"/>
         <inertia ixx="1e-09" iyy="1e-09" izz="1e-09" ixy="0" ixz="0" iyz="0"/>
      </inertial>
   </link>
   <joint type="revolute" name="pinky_abd">
      <parent link="palm"/>
      <child link="pinky_abd_jointbody"/>
      <origin xyz="0.04123255613565277 0.005128234212297354 0.015805277968103645" rpy="-1.5799161189708797 0.9071946146015462 -2.8781819803477346"/>
      <axis xyz="-1.942890293094024e-16 6.661338147750939e-16 -1.0000000000000004"/>
      <limit lower="-0.6108652381980153" upper="0.4363323129985824" effort="100" velocity="100"/>
   </joint>
   <joint type="fixed" name="pinky_abd_offset">
      <parent link="pinky_abd_jointbody"/>
      <child link="pinky_um"/>
      <origin xyz="-0.014400000000000012 2.211772431870429e-17 -1.5178830414797062e-17" rpy="0.0 0.0 0.0"/>
   </joint>
   <link name="pinky_pp">
      <inertial>
         <origin xyz="0.0011081239410495802 -6.835791393050442e-07 0.016046375623555865" rpy="0.0013778191143609397 -0.0356616612010936 -0.04982590931331974"/>
         <mass value="0.009193689280540233"/>
         <inertia ixx="8.415561519046092e-07" iyy="8.352213456647945e-07" izz="2.602923288447009e-07" ixy="0" ixz="0" iyz="0"/>
      </inertial>
      <visual name="pinky_pp">
         <origin xyz="0.0011081239410495802 -6.835791393050442e-07 0.016046375623555865" rpy="0.0013778191143609397 -0.0356616612010936 -0.04982590931331974"/>
         <geometry>
            <mesh filename="package://viz/models/orca1_hand/urdf/converted_pinky_pp.stl"/>
         </geometry>
         <material name="white"/>
      </visual>
   </link>
   <link name="root2pinky_pp_jointbody">
      <inertial>
         <origin xyz="0.0 0.0 0.0" rpy="0.0 0.0 0.0"/>
         <mass value="0.001"/>
         <inertia ixx="1e-09" iyy="1e-09" izz="1e-09" ixy="0" ixz="0" iyz="0"/>
      </inertial>
   </link>
   <joint type="revolute" name="root2pinky_pp">
      <parent link="pinky_um"/>
      <child link="root2pinky_pp_jointbody"/>
      <origin xyz="3.525016089636266e-17 -3.1056381288997515e-19 2.7390067716395695e-17" rpy="3.141592653589439 -1.5692446522906773 -3.141592653589439"/>
      <axis xyz="-3.885780586188048e-16 -1.0000000000000004 -2.636779683484747e-16"/>
      <limit lower="-0.17453292519943295" upper="2.007128639793479" effort="100" velocity="100"/>
   </joint>
   <joint type="fixed" name="root2pinky_pp_offset">
      <parent link="root2pinky_pp_jointbody"/>
      <child link="pinky_pp"/>
      <origin xyz="-3.833184058085544e-18 7.922763782835389e-18 1.4973823299787632e-17" rpy="0.0 0.0 0.0"/>
   </joint>
   <link name="pinky_mp">
      <inertial>
         <origin xyz="0.0014457760100068154 8.307526209729058e-05 0.014984285891448386" rpy="0.030434030316509056 -0.009961283507679886 0.10995570955517174"/>
         <mass value="0.007256911934241935"/>
         <inertia ixx="4.939234421836949e-07" iyy="4.903790475873879e-07" izz="1.9645010163470517e-07" ixy="0" ixz="0" iyz="0"/>
      </inertial>
      <visual name="pinky_mp">
         <origin xyz="0.0014457760100068154 8.307526209729058e-05 0.014984285891448386" rpy="0.030434030316509056 -0.009961283507679886 0.10995570955517174"/>
         <geometry>
            <mesh filename="package://viz/models/orca1_hand/urdf/converted_pinky_mp.stl"/>
         </geometry>
         <material name="white"/>
      </visual>
   </link>
   <link name="pinky_pp2mp_jointbody">
      <inertial>
         <origin xyz="0.0 0.0 0.0" rpy="0.0 0.0 0.0"/>
         <mass value="0.001"/>
         <inertia ixx="1e-09" iyy="1e-09" izz="1e-09" ixy="0" ixz="0" iyz="0"/>
      </inertial>
   </link>
   <joint type="revolute" name="pinky_pp2mp">
      <parent link="pinky_pp"/>
      <child link="pinky_pp2mp_jointbody"/>
      <origin xyz="-2.02538279309526e-17 -3.2474578016063654e-17 0.03000000000000008" rpy="-5.551115123125783e-17 0.0 0.0"/>
      <axis xyz="-4.440892098500626e-16 -1.0000000000000004 -8.326672684688674e-17"/>
      <limit lower="0.0" upper="2.0943951023931953" effort="100" velocity="100"/>
   </joint>
   <joint type="fixed" name="pinky_pp2mp_offset">
      <parent link="pinky_pp2mp_jointbody"/>
      <child link="pinky_mp"/>
      <origin xyz="1.171869695207721e-18 -8.725104538385514e-18 -2.4424879789821522e-17" rpy="0.0 0.0 0.0"/>
   </joint>
   <link name="pinky_dp">
      <inertial>
         <origin xyz="0.010962775970379684 -0.0009207287499492076 0.007029609248376971" rpy="0.0038044439296488486 0.009595151767842092 1.742992635465892"/>
         <mass value="0.009142007854382036"/>
         <inertia ixx="7.030009842186787e-07" iyy="6.96709959144247e-07" izz="2.9942656232517023e-07" ixy="0" ixz="0" iyz="0"/>
      </inertial>
      <visual name="pinky_dp">
         <origin xyz="0.010962775970379684 -0.0009207287499492076 0.007029609248376971" rpy="0.0038044439296489596 0.009595151767842092 1.7429926354658922"/>
         <geometry>
            <mesh filename="package://viz/models/orca1_hand/urdf/converted_pinky_dp.stl"/>
         </geometry>
         <material name="white"/>
      </visual>
   </link>
   <link name="pinky_mp2dp_jointbody">
      <inertial>
         <origin xyz="0.0 0.0 0.0" rpy="0.0 0.0 0.0"/>
         <mass value="0.001"/>
         <inertia ixx="1e-09" iyy="1e-09" izz="1e-09" ixy="0" ixz="0" iyz="0"/>
      </inertial>
   </link>
   <joint type="revolute" name="pinky_mp2dp">
      <parent link="pinky_mp"/>
      <child link="pinky_mp2dp_jointbody"/>
      <origin xyz="0.0010000000000103548 -1.148039996401451e-14 0.02799999999999978" rpy="1.7696955012524995e-13 -1.5853984791647235e-13 1.5707963267948981"/>
      <axis xyz="-0.9999999999999996 2.3037127760972e-15 1.584097436557741e-13"/>
      <limit lower="0.0" upper="1.3089969389957472" effort="100" velocity="100"/>
   </joint>
   <joint type="fixed" name="pinky_mp2dp_offset">
      <parent link="pinky_mp2dp_jointbody"/>
      <child link="pinky_dp"/>
      <origin xyz="-0.011000000000000044 7.281470469290411e-06 0.00900728147046922" rpy="0.0 0.0 0.0"/>
   </joint>
   <link name="pinky_fingertip">
      <inertial>
         <origin xyz="0.011 0.0 0.022" rpy="0.0 0.0 0.0"/>
         <mass value="0.0"/>
         <inertia ixx="0.0" iyy="0.0" izz="0.0" ixy="0" ixz="0" iyz="0"/>
      </inertial>
   </link>
   <link name="pinky_dp2pinky_fingertip_fixed_jointbody">
      <inertial>
         <origin xyz="0.0 0.0 0.0" rpy="0.0 0.0 0.0"/>
         <mass value="0.001"/>
         <inertia ixx="1e-09" iyy="1e-09" izz="1e-09" ixy="0" ixz="0" iyz="0"/>
      </inertial>
   </link>
   <joint type="fixed" name="pinky_dp2pinky_fingertip_fixed">
      <parent link="pinky_dp"/>
      <child link="pinky_dp2pinky_fingertip_fixed_jointbody"/>
      <origin xyz="0.011 0.0 0.022" rpy="0.0 0.0 0.0"/>
   </joint>
   <joint type="fixed" name="pinky_dp2pinky_fingertip_fixed_offset">
      <parent link="pinky_dp2pinky_fingertip_fixed_jointbody"/>
      <child link="pinky_fingertip"/>
      <origin xyz="-0.0 -0.0 -0.0" rpy="0.0 0.0 0.0"/>
   </joint>
   <link name="ring_um">
      <inertial>
         <origin xyz="0.006732763304155957 4.001088863436687e-09 -2.0258619702217643e-05" rpy="-3.131684616200393 -1.561854856603541 -0.009908433449917098"/>
         <mass value="0.002607186033198995"/>
         <inertia ixx="1.3807074528604164e-07" iyy="1.1778104249469416e-07" izz="6.49217043247213e-08" ixy="0" ixz="0" iyz="0"/>
      </inertial>
      <visual name="ring_um">
         <origin xyz="0.006732763304155957 4.001088863436687e-09 -2.0258619702217643e-05" rpy="-3.131684616200393 -1.561854856603541 -0.009908433449916876"/>
         <geometry>
            <mesh filename="package://viz/models/orca1_hand/urdf/converted_ring_um.stl"/>
         </geometry>
         <material name="white"/>
      </visual>
   </link>
   <link name="ring_abd_jointbody">
      <inertial>
         <origin xyz="0.0 0.0 0.0" rpy="0.0 0.0 0.0"/>
         <mass value="0.001"/>
         <inertia ixx="1e-09" iyy="1e-09" izz="1e-09" ixy="0" ixz="0" iyz="0"/>
      </inertial>
   </link>
   <joint type="revolute" name="ring_abd">
      <parent link="palm"/>
      <child link="ring_abd_jointbody"/>
      <origin xyz="0.019694864162417412 0.0013825982229840321 0.030586364349873787" rpy="-1.5707963267948921 1.3088618425821554 -3.054326190990074"/>
      <axis xyz="-8.004708007547379e-14 -1.9984014443252818e-14 0.9999999999999978"/>
      <limit lower="-0.4363323129985824" upper="0.6108652381980153" effort="100" velocity="100"/>
   </joint>
   <joint type="fixed" name="ring_abd_offset">
      <parent link="ring_abd_jointbody"/>
      <child link="ring_um"/>
      <origin xyz="-0.014400000000000029 3.5561831257524545e-17 8.239936510889834e-18" rpy="0.0 0.0 0.0"/>
   </joint>
   <link name="ring_pp">
      <inertial>
         <origin xyz="0.0008060372442654997 -2.635575618623248e-06 0.025309358745536116" rpy="-0.01791413400350872 0.00043408652954268767 1.579449867412698"/>
         <mass value="0.015838995744240178"/>
         <inertia ixx="2.9142748363999414e-06" iyy="2.881065309255171e-06" izz="4.6634203018917616e-07" ixy="0" ixz="0" iyz="0"/>
      </inertial>
      <visual name="ring_pp">
         <origin xyz="0.0008060372442654997 -2.635575618623248e-06 0.025309358745536116" rpy="-0.01791413400350872 0.00043408652954268767 1.579449867412698"/>
         <geometry>
            <mesh filename="package://viz/models/orca1_hand/urdf/converted_ring_pp.stl"/>
         </geometry>
         <material name="white"/>
      </visual>
   </link>
   <link name="root2ring_pp_jointbody">
      <inertial>
         <origin xyz="0.0 0.0 0.0" rpy="0.0 0.0 0.0"/>
         <mass value="0.001"/>
         <inertia ixx="1e-09" iyy="1e-09" izz="1e-09" ixy="0" ixz="0" iyz="0"/>
      </inertial>
   </link>
   <joint type="revolute" name="root2ring_pp">
      <parent link="ring_um"/>
      <child link="root2ring_pp_jointbody"/>
      <origin xyz="8.76421389591046e-16 -6.591883351625457e-14 -5.609920274269105e-15" rpy="3.1415926535778085 -1.5690952335036443 -3.1415926535768572"/>
      <axis xyz="2.1538326677728037e-14 -1.0000000000000016 9.536885170469134e-13"/>
      <limit lower="-0.17453292519943295" upper="2.007128639793479" effort="100" velocity="100"/>
   </joint>
   <joint type="fixed" name="root2ring_pp_offset">
      <parent link="root2ring_pp_jointbody"/>
      <child link="ring_pp"/>
      <origin xyz="-9.795286269233676e-19 -1.4465518891423126e-19 1.4329772049885697e-17" rpy="0.0 0.0 0.0"/>
   </joint>
   <link name="ring_mp">
      <inertial>
         <origin xyz="0.0014457760100068154 8.307526209729058e-05 0.014984285891448386" rpy="0.030434030316509056 -0.009961283507679886 0.10995570955517174"/>
         <mass value="0.007256911934241935"/>
         <inertia ixx="4.939234421836949e-07" iyy="4.903790475873879e-07" izz="1.9645010163470517e-07" ixy="0" ixz="0" iyz="0"/>
      </inertial>
      <visual name="ring_mp">
         <origin xyz="0.0014457760100068154 8.307526209729058e-05 0.014984285891448386" rpy="0.030434030316509056 -0.009961283507679886 0.10995570955517174"/>
         <geometry>
            <mesh filename="package://viz/models/orca1_hand/urdf/converted_ring_mp.stl"/>
         </geometry>
         <material name="white"/>
      </visual>
   </link>
   <link name="ring_pp2mp_jointbody">
      <inertial>
         <origin xyz="0.0 0.0 0.0" rpy="0.0 0.0 0.0"/>
         <mass value="0.001"/>
         <inertia ixx="1e-09" iyy="1e-09" izz="1e-09" ixy="0" ixz="0" iyz="0"/>
      </inertial>
   </link>
   <joint type="revolute" name="ring_pp2mp">
      <parent link="ring_pp"/>
      <child link="ring_pp2mp_jointbody"/>
      <origin xyz="1.6557794334752767e-17 1.0283099349852077e-16 0.048000000000000105" rpy="-8.326672684688684e-17 4.440892098500626e-16 -4.440892098500627e-16"/>
      <axis xyz="5.551115123125783e-17 -0.9999999999999998 1.6514567491299204e-15"/>
      <limit lower="0.0" upper="2.0943951023931953" effort="100" velocity="100"/>
   </joint>
   <joint type="fixed" name="ring_pp2mp_offset">
      <parent link="ring_pp2mp_jointbody"/>
      <child link="ring_mp"/>
      <origin xyz="-2.4797730845642552e-17 -9.545841872561936e-17 -2.5561932479781495e-17" rpy="0.0 0.0 0.0"/>
   </joint>
   <link name="ring_dp">
      <inertial>
         <origin xyz="0.010962775970379684 -0.0009207287499492076 0.007029609248376971" rpy="0.0038044439296488486 0.009595151767842092 1.742992635465892"/>
         <mass value="0.009142007854382036"/>
         <inertia ixx="7.030009842186787e-07" iyy="6.96709959144247e-07" izz="2.9942656232517023e-07" ixy="0" ixz="0" iyz="0"/>
      </inertial>
      <visual name="ring_dp">
         <origin xyz="0.010962775970379684 -0.0009207287499492076 0.007029609248376971" rpy="0.0038044439296489596 0.009595151767842092 1.7429926354658922"/>
         <geometry>
            <mesh filename="package://viz/models/orca1_hand/urdf/converted_ring_dp.stl"/>
         </geometry>
         <material name="white"/>
      </visual>
   </link>
   <link name="ring_mp2dp_jointbody">
      <inertial>
         <origin xyz="0.0 0.0 0.0" rpy="0.0 0.0 0.0"/>
         <mass value="0.001"/>
         <inertia ixx="1e-09" iyy="1e-09" izz="1e-09" ixy="0" ixz="0" iyz="0"/>
      </inertial>
   </link>
   <joint type="revolute" name="ring_mp2dp">
      <parent link="ring_mp"/>
      <child link="ring_mp2dp_jointbody"/>
      <origin xyz="0.0010000000000000247 1.5785983631388945e-16 0.02800000000000006" rpy="-1.4432899320127035e-15 -2.886579864025407e-15 1.570796326794897"/>
      <axis xyz="-1.0000000000000004 9.71445146547012e-17 4.7009379895712744e-15"/>
      <limit lower="0.0" upper="1.3089969389957472" effort="100" velocity="100"/>
   </joint>
   <joint type="fixed" name="ring_mp2dp_offset">
      <parent link="ring_mp2dp_jointbody"/>
      <child link="ring_dp"/>
      <origin xyz="-0.011000000000000136 7.2814704693049395e-06 0.009007281470469263" rpy="0.0 0.0 0.0"/>
   </joint>
   <link name="ring_fingertip">
      <inertial>
         <origin xyz="0.011 0.0 0.022" rpy="0.0 0.0 0.0"/>
         <mass value="0.0"/>
         <inertia ixx="0.0" iyy="0.0" izz="0.0" ixy="0" ixz="0" iyz="0"/>
      </inertial>
   </link>
   <link name="ring_dp2ring_fingertip_fixed_jointbody">
      <inertial>
         <origin xyz="0.0 0.0 0.0" rpy="0.0 0.0 0.0"/>
         <mass value="0.001"/>
         <inertia ixx="1e-09" iyy="1e-09" izz="1e-09" ixy="0" ixz="0" iyz="0"/>
      </inertial>
   </link>
   <joint type="fixed" name="ring_dp2ring_fingertip_fixed">
      <parent link="ring_dp"/>
      <child link="ring_dp2ring_fingertip_fixed_jointbody"/>
      <origin xyz="0.011 0.0 0.022" rpy="0.0 0.0 0.0"/>
   </joint>
   <joint type="fixed" name="ring_dp2ring_fingertip_fixed_offset">
      <parent link="ring_dp2ring_fingertip_fixed_jointbody"/>
      <child link="ring_fingertip"/>
      <origin xyz="-0.0 -0.0 -0.0" rpy="0.0 0.0 0.0"/>
   </joint>
   <link name="thumb_base">
      <inertial>
         <origin xyz="0.008808869187580644 6.0539790788424805e-05 -6.227108387365731e-07" rpy="1.5867431449904335 -1.5487623466463896 1.5779915757952099"/>
         <mass value="0.004343232157026885"/>
         <inertia ixx="3.2542026380799935e-07" iyy="2.8172270770847253e-07" izz="1.4637236276937704e-07" ixy="0" ixz="0" iyz="0"/>
      </inertial>
      <visual name="thumb_base">
         <origin xyz="0.008808869187580644 6.0539790788424805e-05 -6.227108387365731e-07" rpy="1.5867431449904335 -1.5487623466463896 1.5779915757952099"/>
         <geometry>
            <mesh filename="package://viz/models/orca1_hand/urdf/converted_thumb_base.stl"/>
         </geometry>
         <material name="white"/>
      </visual>
   </link>
   <link name="root2thumb_base_jointbody">
      <inertial>
         <origin xyz="0.0 0.0 0.0" rpy="0.0 0.0 0.0"/>
         <mass value="0.001"/>
         <inertia ixx="1e-09" iyy="1e-09" izz="1e-09" ixy="0" ixz="0" iyz="0"/>
      </inertial>
   </link>
   <joint type="revolute" name="root2thumb_base">
      <parent link="palm"/>
      <child link="root2thumb_base_jointbody"/>
      <origin xyz="-0.01933668556029309 0.007354881795979843 -0.02738447811197526" rpy="-2.2765234291633645 0.5077476451224663 -0.8026267442856543"/>
      <axis xyz="1.1657341758564144e-15 -2.220446049250313e-15 -0.9999999999999962"/>
      <limit lower="-1.3089969389957472" upper="1.3089969389957472" effort="100" velocity="100"/>
   </joint>
   <joint type="fixed" name="root2thumb_base_offset">
      <parent link="root2thumb_base_jointbody"/>
      <child link="thumb_base"/>
      <origin xyz="-0.016900000000000366 -6.505213034913027e-17 -1.8106176280507924e-16" rpy="0.0 0.0 0.0"/>
   </joint>
   <link name="thumb_pp">
      <inertial>
         <origin xyz="0.0110035065603882 1.2140320581283004e-05 4.99089698308662e-06" rpy="1.5801938322395839 -1.3458483295749617 1.5649015598749747"/>
         <mass value="0.005082655147362075"/>
         <inertia ixx="5.315792864935883e-07" iyy="4.848428109529283e-07" izz="1.5884694021631092e-07" ixy="0" ixz="0" iyz="0"/>
      </inertial>
      <visual name="thumb_pp">
         <origin xyz="0.0110035065603882 1.2140320581283004e-05 4.99089698308662e-06" rpy="1.5801938322395845 -1.3458483295749617 1.564901559874974"/>
         <geometry>
            <mesh filename="package://viz/models/orca1_hand/urdf/converted_thumb_pp.stl"/>
         </geometry>
         <material name="white"/>
      </visual>
   </link>
   <link name="thumb_base2pp_jointbody">
      <inertial>
         <origin xyz="0.0 0.0 0.0" rpy="0.0 0.0 0.0"/>
         <mass value="0.001"/>
         <inertia ixx="1e-09" iyy="1e-09" izz="1e-09" ixy="0" ixz="0" iyz="0"/>
      </inertial>
   </link>
   <joint type="revolute" name="thumb_base2pp">
      <parent link="thumb_base"/>
      <child link="thumb_base2pp_jointbody"/>
      <origin xyz="6.696032617270475e-16 1.8030049447620726e-16 1.04077532652539e-16" rpy="2.0071286397934847 -2.4424906541753444e-15 -1.5543122344752192e-15"/>
      <axis xyz="1.0824674490095276e-15 -0.42261826174070033 -0.9063077870366472"/>
      <limit lower="-0.7853981633974483" upper="0.7853981633974483" effort="100" velocity="100"/>
   </joint>
   <joint type="fixed" name="thumb_base2pp_offset">
      <parent link="thumb_base2pp_jointbody"/>
      <child link="thumb_pp"/>
      <origin xyz="-0.023000000000001172 -9.367506770274758e-17 -3.499533562240087e-16" rpy="0.0 0.0 0.0"/>
   </joint>
   <link name="thumb_mp">
      <inertial>
         <origin xyz="0.0008671837157415993 3.6807067201715006e-05 0.014545771273496376" rpy="0.00077585773810393 -0.01657317387693391 0.012834020797146971"/>
         <mass value="0.004591034960824554"/>
         <inertia ixx="5.918485249131172e-07" iyy="5.836019355467322e-07" izz="9.196006074468986e-08" ixy="0" ixz="0" iyz="0"/>
      </inertial>
      <visual name="thumb_mp">
         <origin xyz="0.0008671837157415993 3.6807067201715006e-05 0.014545771273496376" rpy="0.00077585773810393 -0.01657317387693391 0.012834020797146971"/>
         <geometry>
            <mesh filename="package://viz/models/orca1_hand/urdf/converted_thumb_mp.stl"/>
         </geometry>
         <material name="white"/>
      </visual>
   </link>
   <link name="thumb_pp2mp_jointbody">
      <inertial>
         <origin xyz="0.0 0.0 0.0" rpy="0.0 0.0 0.0"/>
         <mass value="0.001"/>
         <inertia ixx="1e-09" iyy="1e-09" izz="1e-09" ixy="0" ixz="0" iyz="0"/>
      </inertial>
   </link>
   <joint type="revolute" name="thumb_pp2mp">
      <parent link="thumb_pp"/>
      <child link="thumb_pp2mp_jointbody"/>
      <origin xyz="1.0061975309744072e-15 1.5763860490676992e-16 6.475155218103694e-16" rpy="3.1415926535897905 1.5707963267948797 0.0"/>
      <axis xyz="-6.8833827526759706e-15 -0.9999999999999959 -7.993605777301127e-15"/>
      <limit lower="-0.17453292519943295" upper="1.5707963267948966" effort="100" velocity="100"/>
   </joint>
   <joint type="fixed" name="thumb_pp2mp_offset">
      <parent link="thumb_pp2mp_jointbody"/>
      <child link="thumb_mp"/>
      <origin xyz="-6.8988979146713415e-18 -2.155793885708645e-17 -2.0127088287987651e-16" rpy="0.0 0.0 0.0"/>
   </joint>
   <link name="thumb_dp">
      <inertial>
         <origin xyz="0.010962775970379684 -0.0009207287499492076 0.007029609248376971" rpy="0.0038044439296488486 0.009595151767842092 1.742992635465892"/>
         <mass value="0.009142007854382036"/>
         <inertia ixx="7.030009842186787e-07" iyy="6.96709959144247e-07" izz="2.9942656232517023e-07" ixy="0" ixz="0" iyz="0"/>
      </inertial>
      <visual name="thumb_dp">
         <origin xyz="0.010962775970379684 -0.0009207287499492076 0.007029609248376971" rpy="0.0038044439296489596 0.009595151767842092 1.7429926354658922"/>
         <geometry>
            <mesh filename="package://viz/models/orca1_hand/urdf/converted_thumb_dp.stl"/>
         </geometry>
         <material name="white"/>
      </visual>
   </link>
   <link name="thumb_mp2dp_jointbody">
      <inertial>
         <origin xyz="0.0 0.0 0.0" rpy="0.0 0.0 0.0"/>
         <mass value="0.001"/>
         <inertia ixx="1e-09" iyy="1e-09" izz="1e-09" ixy="0" ixz="0" iyz="0"/>
      </inertial>
   </link>
   <joint type="revolute" name="thumb_mp2dp">
      <parent link="thumb_mp"/>
      <child link="thumb_mp2dp_jointbody"/>
      <origin xyz="1.8258726914308424e-16 5.204170427930421e-16 0.029999999999999895" rpy="2.4424906541753444e-15 -1.2878587085651816e-14 1.5707963267948923"/>
      <axis xyz="-0.9999999999999958 2.9976021664879227e-15 5.287437154777308e-15"/>
      <limit lower="0.0" upper="1.57" effort="100" velocity="100"/>
   </joint>
   <joint type="fixed" name="thumb_mp2dp_offset">
      <parent link="thumb_mp2dp_jointbody"/>
      <child link="thumb_dp"/>
      <origin xyz="-0.011000000000000175 7.281470469432116e-06 0.009007281470469333" rpy="0.0 0.0 0.0"/>
   </joint>
   <link name="thumb_fingertip">
      <inertial>
         <origin xyz="0.011 0.0 0.022" rpy="0.0 0.0 0.0"/>
         <mass value="0.0"/>
         <inertia ixx="0.0" iyy="0.0" izz="0.0" ixy="0" ixz="0" iyz="0"/>
      </inertial>
   </link>
   <link name="thumb_dp2thumb_fingertip_fixed_jointbody">
      <inertial>
         <origin xyz="0.0 0.0 0.0" rpy="0.0 0.0 0.0"/>
         <mass value="0.001"/>
         <inertia ixx="1e-09" iyy="1e-09" izz="1e-09" ixy="0" ixz="0" iyz="0"/>
      </inertial>
   </link>
   <joint type="fixed" name="thumb_dp2thumb_fingertip_fixed">
      <parent link="thumb_dp"/>
      <child link="thumb_dp2thumb_fingertip_fixed_jointbody"/>
      <origin xyz="0.011 0.0 0.022" rpy="0.0 0.0 0.0"/>
   </joint>
   <joint type="fixed" name="thumb_dp2thumb_fingertip_fixed_offset">
      <parent link="thumb_dp2thumb_fingertip_fixed_jointbody"/>
      <child link="thumb_fingertip"/>
      <origin xyz="-0.0 -0.0 -0.0" rpy="0.0 0.0 0.0"/>
   </joint>
   <link name="middle_um">
      <inertial>
         <origin xyz="0.006732763304155957 4.001088863436687e-09 -2.0258619702217643e-05" rpy="-3.131684616200393 -1.561854856603541 -0.009908433449917098"/>
         <mass value="0.002607186033198995"/>
         <inertia ixx="1.3807074528604164e-07" iyy="1.1778104249469416e-07" izz="6.49217043247213e-08" ixy="0" ixz="0" iyz="0"/>
      </inertial>
      <visual name="middle_um">
         <origin xyz="0.006732763304155957 4.001088863436687e-09 -2.0258619702217643e-05" rpy="-3.131684616200393 -1.561854856603541 -0.009908433449916876"/>
         <geometry>
            <mesh filename="package://viz/models/orca1_hand/urdf/converted_middle_um.stl"/>
         </geometry>
         <material name="white"/>
      </visual>
   </link>
   <link name="middle_abd_jointbody">
      <inertial>
         <origin xyz="0.0 0.0 0.0" rpy="0.0 0.0 0.0"/>
         <mass value="0.001"/>
         <inertia ixx="1e-09" iyy="1e-09" izz="1e-09" ixy="0" ixz="0" iyz="0"/>
      </inertial>
   </link>
   <joint type="revolute" name="middle_abd">
      <parent link="palm"/>
      <child link="middle_abd_jointbody"/>
      <origin xyz="-0.0009621394664390548 2.7740667835757045e-18 0.03895854381555531" rpy="1.5707963267948966 1.5707963267948948 0.0"/>
      <axis xyz="1.3877787807814457e-15 1.1102230246251565e-16 0.9999999999999987"/>
      <limit lower="-0.4363323129985824" upper="0.6108652381980153" effort="100" velocity="100"/>
   </joint>
   <joint type="fixed" name="middle_abd_offset">
      <parent link="middle_abd_jointbody"/>
      <child link="middle_um"/>
      <origin xyz="-0.014400000000000015 -2.0816681711721685e-17 2.0383000842727483e-17" rpy="0.0 0.0 0.0"/>
   </joint>
   <link name="middle_pp">
      <inertial>
         <origin xyz="0.0008060372442654997 -2.635575618623248e-06 0.025309358745536116" rpy="-0.01791413400350872 0.00043408652954268767 1.579449867412698"/>
         <mass value="0.015838995744240178"/>
         <inertia ixx="2.9142748363999414e-06" iyy="2.881065309255171e-06" izz="4.6634203018917616e-07" ixy="0" ixz="0" iyz="0"/>
      </inertial>
      <visual name="middle_pp">
         <origin xyz="0.0008060372442654997 -2.635575618623248e-06 0.025309358745536116" rpy="-0.01791413400350872 0.00043408652954268767 1.579449867412698"/>
         <geometry>
            <mesh filename="package://viz/models/orca1_hand/urdf/converted_middle_pp.stl"/>
         </geometry>
         <material name="white"/>
      </visual>
   </link>
   <link name="root2middle_pp_jointbody">
      <inertial>
         <origin xyz="0.0 0.0 0.0" rpy="0.0 0.0 0.0"/>
         <mass value="0.001"/>
         <inertia ixx="1e-09" iyy="1e-09" izz="1e-09" ixy="0" ixz="0" iyz="0"/>
      </inertial>
   </link>
   <joint type="revolute" name="root2middle_pp">
      <parent link="middle_um"/>
      <child link="root2middle_pp_jointbody"/>
      <origin xyz="-2.7755588056615305e-17 2.7755575615628864e-17 6.638549052222253e-21" rpy="3.141592653589793 -1.5689702811526907 3.141592653589793"/>
      <axis xyz="-1.1102230246251565e-16 -1.0000000000000009 9.75781955236954e-18"/>
      <limit lower="-0.17453292519943295" upper="2.007128639793479" effort="100" velocity="100"/>
   </joint>
   <joint type="fixed" name="root2middle_pp_offset">
      <parent link="root2middle_pp_jointbody"/>
      <child link="middle_pp"/>
      <origin xyz="1.5108221092759517e-20 -9.7018720948507e-33 1.3877779583938463e-17" rpy="0.0 0.0 0.0"/>
   </joint>
   <link name="middle_mp">
      <inertial>
         <origin xyz="0.0014457760100068154 8.307526209729058e-05 0.014984285891448386" rpy="0.030434030316509056 -0.009961283507679886 0.10995570955517174"/>
         <mass value="0.007256911934241935"/>
         <inertia ixx="4.939234421836949e-07" iyy="4.903790475873879e-07" izz="1.9645010163470517e-07" ixy="0" ixz="0" iyz="0"/>
      </inertial>
      <visual name="middle_mp">
         <origin xyz="0.0014457760100068154 8.307526209729058e-05 0.014984285891448386" rpy="0.030434030316509056 -0.009961283507679886 0.10995570955517174"/>
         <geometry>
            <mesh filename="package://viz/models/orca1_hand/urdf/converted_middle_mp.stl"/>
         </geometry>
         <material name="white"/>
      </visual>
   </link>
   <link name="middle_pp2mp_jointbody">
      <inertial>
         <origin xyz="0.0 0.0 0.0" rpy="0.0 0.0 0.0"/>
         <mass value="0.001"/>
         <inertia ixx="1e-09" iyy="1e-09" izz="1e-09" ixy="0" ixz="0" iyz="0"/>
      </inertial>
   </link>
   <joint type="revolute" name="middle_pp2mp">
      <parent link="middle_pp"/>
      <child link="middle_pp2mp_jointbody"/>
      <origin xyz="-1.8151956462261382e-17 -2.3920210430460702e-18 0.048000000000000154" rpy="6.114900252818245e-17 0.0 0.0"/>
      <axis xyz="-1.6653345369377348e-16 -1.0000000000000004 9.75781955236954e-18"/>
      <limit lower="0.0" upper="2.0943951023931953" effort="100" velocity="100"/>
   </joint>
   <joint type="fixed" name="middle_pp2mp_offset">
      <parent link="middle_pp2mp_jointbody"/>
      <child link="middle_mp"/>
      <origin xyz="-6.817933558779142e-17 -6.938893903907302e-18 7.4224300060933e-20" rpy="0.0 0.0 0.0"/>
   </joint>
   <link name="middle_dp">
      <inertial>
         <origin xyz="0.010962775970379684 -0.0009207287499492076 0.007029609248376971" rpy="0.0038044439296488486 0.009595151767842092 1.742992635465892"/>
         <mass value="0.009142007854382036"/>
         <inertia ixx="7.030009842186787e-07" iyy="6.96709959144247e-07" izz="2.9942656232517023e-07" ixy="0" ixz="0" iyz="0"/>
      </inertial>
      <visual name="middle_dp">
         <origin xyz="0.010962775970379684 -0.0009207287499492076 0.007029609248376971" rpy="0.0038044439296489596 0.009595151767842092 1.7429926354658922"/>
         <geometry>
            <mesh filename="package://viz/models/orca1_hand/urdf/converted_middle_dp.stl"/>
         </geometry>
         <material name="white"/>
      </visual>
   </link>
   <link name="middle_mp2dp_jointbody">
      <inertial>
         <origin xyz="0.0 0.0 0.0" rpy="0.0 0.0 0.0"/>
         <mass value="0.001"/>
         <inertia ixx="1e-09" iyy="1e-09" izz="1e-09" ixy="0" ixz="0" iyz="0"/>
      </inertial>
   </link>
   <joint type="revolute" name="middle_mp2dp">
      <parent link="middle_mp"/>
      <child link="middle_mp2dp_jointbody"/>
      <origin xyz="0.0010000000000037676 -2.2551405187698492e-17 0.027999999999999955" rpy="4.551914400963142e-14 -4.440892098500626e-16 1.5707963267948966"/>
      <axis xyz="-1.0000000000000002 -3.2838929933875956e-17 5.315090385248316e-16"/>
      <limit lower="0.0" upper="1.3089969389957472" effort="100" velocity="100"/>
   </joint>
   <joint type="fixed" name="middle_mp2dp_offset">
      <parent link="middle_mp2dp_jointbody"/>
      <child link="middle_dp"/>
      <origin xyz="-0.011000000000000034 7.28147046937894e-06 0.009007281470469267" rpy="0.0 0.0 0.0"/>
   </joint>
   <link name="middle_fingertip">
      <inertial>
         <origin xyz="0.011 0.0 0.022" rpy="0.0 0.0 0.0"/>
         <mass value="0.0"/>
         <inertia ixx="0.0" iyy="0.0" izz="0.0" ixy="0" ixz="0" iyz="0"/>
      </inertial>
   </link>
   <link name="middle_dp2middle_fingertip_fixed_jointbody">
      <inertial>
         <origin xyz="0.0 0.0 0.0" rpy="0.0 0.0 0.0"/>
         <mass value="0.001"/>
         <inertia ixx="1e-09" iyy="1e-09" izz="1e-09" ixy="0" ixz="0" iyz="0"/>
      </inertial>
   </link>
   <joint type="fixed" name="middle_dp2middle_fingertip_fixed">
      <parent link="middle_dp"/>
      <child link="middle_dp2middle_fingertip_fixed_jointbody"/>
      <origin xyz="0.011 0.0 0.022" rpy="0.0 0.0 0.0"/>
   </joint>
   <joint type="fixed" name="middle_dp2middle_fingertip_fixed_offset">
      <parent link="middle_dp2middle_fingertip_fixed_jointbody"/>
      <child link="middle_fingertip"/>
      <origin xyz="-0.0 -0.0 -0.0" rpy="0.0 0.0 0.0"/>
   </joint>
   <material name="white">
      <color rgba="1 1 1 1"/>
   </material>
</robot>
