<?xml version="1.0" ?>
<robot name="converted_robot">
   <link name="hand_root">
      <inertial>
         <origin xyz="0.0 0.0 0.0" rpy="0.0 0.0 0.0"/>
         <mass value="0.0"/>
         <inertia ixx="0.0" iyy="0.0" izz="0.0" ixy="0" ixz="0" iyz="0"/>
      </inertial>
   </link>
   <link name="tower">
      <inertial>
         <origin xyz="0.06437901782600965 1.780279318620321e-05 -0.0003231375226686683" rpy="1.5837086827349487 -0.0029817795619724308 1.5715354932140642"/>
         <mass value="1.1686649766962816"/>
         <inertia ixx="0.0019657087041747615" iyy="0.0017826228325031161" izz="0.0006871001143970954" ixy="0" ixz="0" iyz="0"/>
      </inertial>
      <visual name="tower">
         <origin xyz="0.06437901782600965 1.780279318620321e-05 -0.0003231375226686683" rpy="1.5837086827349485 -0.0029817795619724308 1.5715354932140644"/>
         <geometry>
            <mesh filename="package://viz/models/orca2_hand/urdf/converted_tower.stl"/>
         </geometry>
         <material name="white"/>
      </visual>
   </link>
   <link name="root2tower_fixed_jointbody">
      <inertial>
         <origin xyz="0.0 0.0 0.0" rpy="0.0 0.0 0.0"/>
         <mass value="0.001"/>
         <inertia ixx="1e-09" iyy="1e-09" izz="1e-09" ixy="0" ixz="0" iyz="0"/>
      </inertial>
   </link>
   <joint type="fixed" name="root2tower_fixed">
      <parent link="hand_root"/>
      <child link="root2tower_fixed_jointbody"/>
      <origin xyz="0.0 0.0 0.0" rpy="0.0 0.0 0.0"/>
   </joint>
   <joint type="fixed" name="root2tower_fixed_offset">
      <parent link="root2tower_fixed_jointbody"/>
      <child link="tower"/>
      <origin xyz="-0.0 -0.0 -0.0" rpy="0.0 0.0 0.0"/>
   </joint>
   <link name="palm">
      <inertial>
         <origin xyz="0.0031912473878069774 -0.0006749899283967215 -0.015136850518871516" rpy="0.11405696582152314 0.0015084000918792473 1.5488013055321626"/>
         <mass value="0.15921340555544056"/>
         <inertia ixx="0.00012037851270871299" iyy="8.589315006598176e-05" izz="4.155619420983368e-05" ixy="0" ixz="0" iyz="0"/>
      </inertial>
      <visual name="palm_tower">
         <origin xyz="0.0031912473878069774 -0.0006749899283967215 -0.015136850518871516" rpy="0.11405696582152303 0.0015084000918792473 1.5488013055321623"/>
         <geometry>
            <mesh filename="package://viz/models/orca2_hand/urdf/converted_palm_tower.stl"/>
         </geometry>
         <material name="white"/>
      </visual>
   </link>
   <link name="tower2root_jointbody">
      <inertial>
         <origin xyz="0.0 0.0 0.0" rpy="0.0 0.0 0.0"/>
         <mass value="0.001"/>
         <inertia ixx="1e-09" iyy="1e-09" izz="1e-09" ixy="0" ixz="0" iyz="0"/>
      </inertial>
   </link>
   <joint type="revolute" name="tower2root">
      <parent link="tower"/>
      <child link="tower2root_jointbody"/>
      <origin xyz="0.144 5.994002132739204e-18 -4.119968255444917e-17" rpy="-0.0 1.5707963267948957 0.0"/>
      <axis xyz="0.9999999999999996 -1.0755285551056194e-15 4.9303806576312877e-32"/>
      <limit lower="-1.3962634015954636" upper="1.3962634015954636" effort="100" velocity="100"/>
   </joint>
   <joint type="fixed" name="tower2root_offset">
      <parent link="tower2root_jointbody"/>
      <child link="palm"/>
      <origin xyz="-0.0020000000000000035 -2.71190195469167e-33 0.05000000000000001" rpy="0.0 0.0 0.0"/>
   </joint>
   <link name="index_um">
      <inertial>
         <origin xyz="0.006732763304155957 4.001088863436687e-09 -2.0258619702217643e-05" rpy="-3.131684616200393 -1.561854856603541 -0.009908433449917098"/>
         <mass value="0.002607186033198995"/>
         <inertia ixx="1.3807074528604164e-07" iyy="1.1778104249469416e-07" izz="6.49217043247213e-08" ixy="0" ixz="0" iyz="0"/>
      </inertial>
      <visual name="index_um">
         <origin xyz="0.006732763304155957 4.001088863436687e-09 -2.0258619702217643e-05" rpy="-3.131684616200393 -1.561854856603541 -0.009908433449916876"/>
         <geometry>
            <mesh filename="package://viz/models/orca2_hand/urdf/converted_index_um.stl"/>
         </geometry>
         <material name="white"/>
      </visual>
   </link>
   <link name="index_abd_jointbody">
      <inertial>
         <origin xyz="0.0 0.0 0.0" rpy="0.0 0.0 0.0"/>
         <mass value="0.001"/>
         <inertia ixx="1e-09" iyy="1e-09" izz="1e-09" ixy="0" ixz="0" iyz="0"/>
      </inertial>
   </link>
   <joint type="revolute" name="index_abd">
      <parent link="palm"/>
      <child link="index_abd_jointbody"/>
      <origin xyz="-0.02202689829157017 0.0015684105070723296 0.035558225043102326" rpy="1.6580627893946036 1.3962634015954642 -9.658940314238862e-15"/>
      <axis xyz="1.942890293094024e-15 -1.1102230246251565e-16 0.9999999999999977"/>
      <limit lower="-0.4363323129985824" upper="0.6108652381980153" effort="100" velocity="100"/>
   </joint>
   <joint type="fixed" name="index_abd_offset">
      <parent link="index_abd_jointbody"/>
      <child link="index_um"/>
      <origin xyz="-0.0144 7.068998164605489e-17 -9.540979117872439e-18" rpy="0.0 0.0 0.0"/>
   </joint>
   <link name="index_pp">
      <inertial>
         <origin xyz="0.0008687401920092231 -2.4862054760042404e-05 0.022247108199277357" rpy="-0.00113071384580111 -0.012433056943532472 0.0237556697838349"/>
         <mass value="0.006075709241757069"/>
         <inertia ixx="1.2759699630750096e-06" iyy="1.261715939586915e-06" izz="1.1563772656262221e-07" ixy="0" ixz="0" iyz="0"/>
      </inertial>
      <visual name="index_pp">
         <origin xyz="0.0008687401920092231 -2.4862054760042404e-05 0.022247108199277357" rpy="-0.0011307138458011082 -0.012433056943532472 0.0237556697838349"/>
         <geometry>
            <mesh filename="package://viz/models/orca2_hand/urdf/converted_index_pp.stl"/>
         </geometry>
         <material name="white"/>
      </visual>
   </link>
   <link name="root2index_pp_jointbody">
      <inertial>
         <origin xyz="0.0 0.0 0.0" rpy="0.0 0.0 0.0"/>
         <mass value="0.001"/>
         <inertia ixx="1e-09" iyy="1e-09" izz="1e-09" ixy="0" ixz="0" iyz="0"/>
      </inertial>
   </link>
   <joint type="revolute" name="root2index_pp">
      <parent link="index_um"/>
      <child link="root2index_pp_jointbody"/>
      <origin xyz="3.9606233593205086e-17 -9.422367056560164e-17 1.3685221253534087e-17" rpy="-3.140184917367559e-16 -1.5707963267948915 0.0"/>
      <axis xyz="8.326672684688674e-16 -1.0000000000000082 -9.506284648352903e-16"/>
      <limit lower="-0.17453292519943295" upper="2.007128639793479" effort="100" velocity="100"/>
   </joint>
   <joint type="fixed" name="root2index_pp_offset">
      <parent link="root2index_pp_jointbody"/>
      <child link="index_pp"/>
      <origin xyz="-1.0507725389252553e-18 -1.0381299611154882e-17 1.8073894221564938e-18" rpy="0.0 0.0 0.0"/>
   </joint>
   <link name="index_mp">
      <inertial>
         <origin xyz="0.0013909738898894978 0.00016387532873425497 0.014968668474816213" rpy="0.03291128493942308 -0.020555715782136996 1.1076943559460612"/>
         <mass value="0.003108373341414378"/>
         <inertia ixx="3.251881563114705e-07" iyy="3.238587171666197e-07" izz="4.895669014432085e-08" ixy="0" ixz="0" iyz="0"/>
      </inertial>
      <visual name="index_mp">
         <origin xyz="0.0013909738898894978 0.00016387532873425497 0.014968668474816213" rpy="0.03291128493942308 -0.020555715782136774 1.107694355946061"/>
         <geometry>
            <mesh filename="package://viz/models/orca2_hand/urdf/converted_index_mp.stl"/>
         </geometry>
         <material name="white"/>
      </visual>
   </link>
   <link name="index_pp2mp_jointbody">
      <inertial>
         <origin xyz="0.0 0.0 0.0" rpy="0.0 0.0 0.0"/>
         <mass value="0.001"/>
         <inertia ixx="1e-09" iyy="1e-09" izz="1e-09" ixy="0" ixz="0" iyz="0"/>
      </inertial>
   </link>
   <joint type="revolute" name="index_pp2mp">
      <parent link="index_pp"/>
      <child link="index_pp2mp_jointbody"/>
      <origin xyz="-2.0218402492608785e-16 5.368471504812676e-17 0.040000000000000036" rpy="8.187894806610526e-16 4.440892098500626e-16 -6.661338147750935e-16"/>
      <axis xyz="2.7755575615628914e-16 -1.0000000000000036 -1.0408340855860843e-16"/>
      <limit lower="0.0" upper="2.0943951023931953" effort="100" velocity="100"/>
   </joint>
   <joint type="fixed" name="index_pp2mp_offset">
      <parent link="index_pp2mp_jointbody"/>
      <child link="index_mp"/>
      <origin xyz="-3.597547411660925e-18 6.102387480083956e-17 -5.305012189775878e-17" rpy="0.0 0.0 0.0"/>
   </joint>
   <link name="index_dp">
      <inertial>
         <origin xyz="-1.3890187096631583e-05 0.005054400100332685 -0.00020300962240500135" rpy="1.4604505475177294 -0.03444883339617988 0.0022630734580013634"/>
         <mass value="0.0011385821737687244"/>
         <inertia ixx="5.751980191525933e-08" iyy="5.65392336466142e-08" izz="1.0221302805317223e-08" ixy="0" ixz="0" iyz="0"/>
      </inertial>
      <visual name="index_dp">
         <origin xyz="-1.3890187096631583e-05 0.005054400100332685 -0.00020300962240500135" rpy="1.4604505475177294 -0.03444883339617988 0.0022630734580013634"/>
         <geometry>
            <mesh filename="package://viz/models/orca2_hand/urdf/converted_index_dp.stl"/>
         </geometry>
         <material name="white"/>
      </visual>
   </link>
   <link name="index_mp2dp_jointbody">
      <inertial>
         <origin xyz="0.0 0.0 0.0" rpy="0.0 0.0 0.0"/>
         <mass value="0.001"/>
         <inertia ixx="1e-09" iyy="1e-09" izz="1e-09" ixy="0" ixz="0" iyz="0"/>
      </inertial>
   </link>
   <joint type="revolute" name="index_mp2dp">
      <parent link="index_mp"/>
      <child link="index_mp2dp_jointbody"/>
      <origin xyz="0.000999999999999872 -2.15485181781494e-16 0.02799999999999978" rpy="1.5707963267948917 -3.552713678800501e-15 1.5707963267948988"/>
      <axis xyz="-0.9999999999999916 3.6012859361278515e-15 -1.0720591081536668e-15"/>
      <limit lower="0.0" upper="1.3089969389957472" effort="100" velocity="100"/>
   </joint>
   <joint type="fixed" name="index_mp2dp_offset">
      <parent link="index_mp2dp_jointbody"/>
      <child link="index_dp"/>
      <origin xyz="-9.999999999992125e-05 5.378659215064807e-18 1.170176016631816e-18" rpy="0.0 0.0 0.0"/>
   </joint>
   <link name="index_fingertip">
      <inertial>
         <origin xyz="0.0 0.02 -0.001306" rpy="0.0 0.0 0.0"/>
         <mass value="0.0"/>
         <inertia ixx="0.0" iyy="0.0" izz="0.0" ixy="0" ixz="0" iyz="0"/>
      </inertial>
   </link>
   <link name="index_dp2index_fingertip_fixed_jointbody">
      <inertial>
         <origin xyz="0.0 0.0 0.0" rpy="0.0 0.0 0.0"/>
         <mass value="0.001"/>
         <inertia ixx="1e-09" iyy="1e-09" izz="1e-09" ixy="0" ixz="0" iyz="0"/>
      </inertial>
   </link>
   <joint type="fixed" name="index_dp2index_fingertip_fixed">
      <parent link="index_dp"/>
      <child link="index_dp2index_fingertip_fixed_jointbody"/>
      <origin xyz="0.0 0.02 -0.001306" rpy="0.0 0.0 0.0"/>
   </joint>
   <joint type="fixed" name="index_dp2index_fingertip_fixed_offset">
      <parent link="index_dp2index_fingertip_fixed_jointbody"/>
      <child link="index_fingertip"/>
      <origin xyz="-0.0 -0.0 -0.0" rpy="0.0 0.0 0.0"/>
   </joint>
   <link name="pinky_um">
      <inertial>
         <origin xyz="0.006732763304155957 4.001088863436687e-09 -2.0258619702217643e-05" rpy="-3.131684616200393 -1.561854856603541 -0.009908433449917098"/>
         <mass value="0.002607186033198995"/>
         <inertia ixx="1.3807074528604164e-07" iyy="1.1778104249469416e-07" izz="6.49217043247213e-08" ixy="0" ixz="0" iyz="0"/>
      </inertial>
      <visual name="pinky_um">
         <origin xyz="0.006732763304155957 4.001088863436687e-09 -2.0258619702217643e-05" rpy="-3.131684616200393 -1.561854856603541 -0.009908433449916876"/>
         <geometry>
            <mesh filename="package://viz/models/orca2_hand/urdf/converted_pinky_um.stl"/>
         </geometry>
         <material name="white"/>
      </visual>
   </link>
   <link name="pinky_abd_jointbody">
      <inertial>
         <origin xyz="0.0 0.0 0.0" rpy="0.0 0.0 0.0"/>
         <mass value="0.001"/>
         <inertia ixx="1e-09" iyy="1e-09" izz="1e-09" ixy="0" ixz="0" iyz="0"/>
      </inertial>
   </link>
   <joint type="revolute" name="pinky_abd">
      <parent link="palm"/>
      <child link="pinky_abd_jointbody"/>
      <origin xyz="0.04123255613565274 0.005128234212297326 0.015805277968103576" rpy="-1.579920941226867 0.9076077576902897 -2.878188100691394"/>
      <axis xyz="-2.7755575615628914e-17 -1.6653345369377348e-16 -1.0000000000000009"/>
      <limit lower="-0.6108652381980153" upper="0.4363323129985824" effort="100" velocity="100"/>
   </joint>
   <joint type="fixed" name="pinky_abd_offset">
      <parent link="pinky_abd_jointbody"/>
      <child link="pinky_um"/>
      <origin xyz="-0.014400000000000007 1.1275702593849246e-17 -1.5829351718288365e-17" rpy="0.0 0.0 0.0"/>
   </joint>
   <link name="pinky_pp">
      <inertial>
         <origin xyz="0.0008258154520941577 -2.2222565756841063e-05 0.016729787379917885" rpy="-0.0012233283283072625 -0.019834837027373764 0.012268708074692703"/>
         <mass value="0.0046751560406718806"/>
         <inertia ixx="6.47008260669387e-07" iyy="6.357773713013815e-07" izz="9.004187327563991e-08" ixy="0" ixz="0" iyz="0"/>
      </inertial>
      <visual name="pinky_pp">
         <origin xyz="0.0008258154520941577 -2.2222565756841063e-05 0.016729787379917885" rpy="-0.0012233283283072625 -0.019834837027373764 0.012268708074692703"/>
         <geometry>
            <mesh filename="package://viz/models/orca2_hand/urdf/converted_pinky_pp.stl"/>
         </geometry>
         <material name="white"/>
      </visual>
   </link>
   <link name="root2pinky_pp_jointbody">
      <inertial>
         <origin xyz="0.0 0.0 0.0" rpy="0.0 0.0 0.0"/>
         <mass value="0.001"/>
         <inertia ixx="1e-09" iyy="1e-09" izz="1e-09" ixy="0" ixz="0" iyz="0"/>
      </inertial>
   </link>
   <joint type="revolute" name="root2pinky_pp">
      <parent link="pinky_um"/>
      <child link="root2pinky_pp_jointbody"/>
      <origin xyz="1.7702462397522765e-17 -1.1331096051742205e-17 -6.361123313678201e-18" rpy="-7.850462293418875e-17 -1.5707963267948963 0.0"/>
      <axis xyz="-3.885780586188048e-16 -0.9999999999999996 -8.465450562766819e-16"/>
      <limit lower="-0.17453292519943295" upper="2.007128639793479" effort="100" velocity="100"/>
   </joint>
   <joint type="fixed" name="root2pinky_pp_offset">
      <parent link="root2pinky_pp_jointbody"/>
      <child link="pinky_pp"/>
      <origin xyz="3.237906566374557e-18 2.1668957835962876e-18 -1.5894815400683688e-17" rpy="0.0 0.0 0.0"/>
   </joint>
   <link name="pinky_mp">
      <inertial>
         <origin xyz="0.0013909738898894978 0.00016387532873425497 0.014968668474816213" rpy="0.03291128493942308 -0.020555715782136996 1.1076943559460612"/>
         <mass value="0.003108373341414378"/>
         <inertia ixx="3.251881563114705e-07" iyy="3.238587171666197e-07" izz="4.895669014432085e-08" ixy="0" ixz="0" iyz="0"/>
      </inertial>
      <visual name="pinky_mp">
         <origin xyz="0.0013909738898894978 0.00016387532873425497 0.014968668474816213" rpy="0.03291128493942308 -0.020555715782136774 1.107694355946061"/>
         <geometry>
            <mesh filename="package://viz/models/orca2_hand/urdf/converted_pinky_mp.stl"/>
         </geometry>
         <material name="white"/>
      </visual>
   </link>
   <link name="pinky_pp2mp_jointbody">
      <inertial>
         <origin xyz="0.0 0.0 0.0" rpy="0.0 0.0 0.0"/>
         <mass value="0.001"/>
         <inertia ixx="1e-09" iyy="1e-09" izz="1e-09" ixy="0" ixz="0" iyz="0"/>
      </inertial>
   </link>
   <joint type="revolute" name="pinky_pp2mp">
      <parent link="pinky_pp"/>
      <child link="pinky_pp2mp_jointbody"/>
      <origin xyz="1.652844361054724e-18 -2.6807287263060844e-18 0.03000000000000004" rpy="2.49800180540661e-16 5.773159728050814e-15 7.395570986446986e-31"/>
      <axis xyz="-4.996003610813204e-16 -1.0000000000000064 -1.249000902703301e-16"/>
      <limit lower="0.0" upper="2.0943951023931953" effort="100" velocity="100"/>
   </joint>
   <joint type="fixed" name="pinky_pp2mp_offset">
      <parent link="pinky_pp2mp_jointbody"/>
      <child link="pinky_mp"/>
      <origin xyz="-8.591738264962151e-18 -2.3773804282340214e-17 3.419878436337367e-17" rpy="0.0 0.0 0.0"/>
   </joint>
   <link name="pinky_dp">
      <inertial>
         <origin xyz="-1.3890187096631583e-05 0.005054400100332685 -0.00020300962240500135" rpy="1.4604505475177294 -0.03444883339617988 0.0022630734580013634"/>
         <mass value="0.0011385821737687244"/>
         <inertia ixx="5.751980191525933e-08" iyy="5.65392336466142e-08" izz="1.0221302805317223e-08" ixy="0" ixz="0" iyz="0"/>
      </inertial>
      <visual name="pinky_dp">
         <origin xyz="-1.3890187096631583e-05 0.005054400100332685 -0.00020300962240500135" rpy="1.4604505475177294 -0.03444883339617988 0.0022630734580013634"/>
         <geometry>
            <mesh filename="package://viz/models/orca2_hand/urdf/converted_pinky_dp.stl"/>
         </geometry>
         <material name="white"/>
      </visual>
   </link>
   <link name="pinky_mp2dp_jointbody">
      <inertial>
         <origin xyz="0.0 0.0 0.0" rpy="0.0 0.0 0.0"/>
         <mass value="0.001"/>
         <inertia ixx="1e-09" iyy="1e-09" izz="1e-09" ixy="0" ixz="0" iyz="0"/>
      </inertial>
   </link>
   <joint type="revolute" name="pinky_mp2dp">
      <parent link="pinky_mp"/>
      <child link="pinky_mp2dp_jointbody"/>
      <origin xyz="0.0009999999999998701 2.946319403729358e-17 0.028000000000000025" rpy="1.5707963267948906 -6.661338147750939e-16 1.5707963267948968"/>
      <axis xyz="-0.9999999999999996 2.7755575615628914e-16 -4.718447854656915e-16"/>
      <limit lower="0.0" upper="1.3089969389957472" effort="100" velocity="100"/>
   </joint>
   <joint type="fixed" name="pinky_mp2dp_offset">
      <parent link="pinky_mp2dp_jointbody"/>
      <child link="pinky_dp"/>
      <origin xyz="-0.00010000000000000671 -4.875352237806302e-17 -1.2314164987183018e-17" rpy="0.0 0.0 0.0"/>
   </joint>
   <link name="pinky_fingertip">
      <inertial>
         <origin xyz="0.0 0.02 -0.001306" rpy="0.0 0.0 0.0"/>
         <mass value="0.0"/>
         <inertia ixx="0.0" iyy="0.0" izz="0.0" ixy="0" ixz="0" iyz="0"/>
      </inertial>
   </link>
   <link name="pinky_dp2pinky_fingertip_fixed_jointbody">
      <inertial>
         <origin xyz="0.0 0.0 0.0" rpy="0.0 0.0 0.0"/>
         <mass value="0.001"/>
         <inertia ixx="1e-09" iyy="1e-09" izz="1e-09" ixy="0" ixz="0" iyz="0"/>
      </inertial>
   </link>
   <joint type="fixed" name="pinky_dp2pinky_fingertip_fixed">
      <parent link="pinky_dp"/>
      <child link="pinky_dp2pinky_fingertip_fixed_jointbody"/>
      <origin xyz="0.0 0.02 -0.001306" rpy="0.0 0.0 0.0"/>
   </joint>
   <joint type="fixed" name="pinky_dp2pinky_fingertip_fixed_offset">
      <parent link="pinky_dp2pinky_fingertip_fixed_jointbody"/>
      <child link="pinky_fingertip"/>
      <origin xyz="-0.0 -0.0 -0.0" rpy="0.0 0.0 0.0"/>
   </joint>
   <link name="ring_um">
      <inertial>
         <origin xyz="0.006732763304155957 4.001088863436687e-09 -2.0258619702217643e-05" rpy="-3.131684616200393 -1.561854856603541 -0.009908433449917098"/>
         <mass value="0.002607186033198995"/>
         <inertia ixx="1.3807074528604164e-07" iyy="1.1778104249469416e-07" izz="6.49217043247213e-08" ixy="0" ixz="0" iyz="0"/>
      </inertial>
      <visual name="ring_um">
         <origin xyz="0.006732763304155957 4.001088863436687e-09 -2.0258619702217643e-05" rpy="-3.131684616200393 -1.561854856603541 -0.009908433449916876"/>
         <geometry>
            <mesh filename="package://viz/models/orca2_hand/urdf/converted_ring_um.stl"/>
         </geometry>
         <material name="white"/>
      </visual>
   </link>
   <link name="ring_abd_jointbody">
      <inertial>
         <origin xyz="0.0 0.0 0.0" rpy="0.0 0.0 0.0"/>
         <mass value="0.001"/>
         <inertia ixx="1e-09" iyy="1e-09" izz="1e-09" ixy="0" ixz="0" iyz="0"/>
      </inertial>
   </link>
   <joint type="revolute" name="ring_abd">
      <parent link="palm"/>
      <child link="ring_abd_jointbody"/>
      <origin xyz="0.019694864162417454 0.0013825982229840484 0.030586364349873843" rpy="-1.5707963267948946 1.308996938995747 -3.054326190990076"/>
      <axis xyz="-8.326672684688674e-17 2.220446049250313e-16 0.9999999999999979"/>
      <limit lower="-0.4363323129985824" upper="0.6108652381980153" effort="100" velocity="100"/>
   </joint>
   <joint type="fixed" name="ring_abd_offset">
      <parent link="ring_abd_jointbody"/>
      <child link="ring_um"/>
      <origin xyz="-0.014399999999999923 5.2475385148298415e-17 3.903127820947816e-18" rpy="0.0 0.0 0.0"/>
   </joint>
   <link name="ring_pp">
      <inertial>
         <origin xyz="0.0008879048431632835 -2.537949357785257e-05 0.026668810452510044" rpy="-0.0011314495857910837 -0.009859569454313544 0.029169093210231874"/>
         <mass value="0.007199054377400034"/>
         <inertia ixx="2.0187701497182777e-06" iyy="2.002065106814579e-06" izz="1.361803516902417e-07" ixy="0" ixz="0" iyz="0"/>
      </inertial>
      <visual name="ring_pp">
         <origin xyz="0.0008879048431632835 -2.537949357785257e-05 0.026668810452510044" rpy="-0.0011314495857910837 -0.009859569454313544 0.029169093210231874"/>
         <geometry>
            <mesh filename="package://viz/models/orca2_hand/urdf/converted_ring_pp.stl"/>
         </geometry>
         <material name="white"/>
      </visual>
   </link>
   <link name="root2ring_pp_jointbody">
      <inertial>
         <origin xyz="0.0 0.0 0.0" rpy="0.0 0.0 0.0"/>
         <mass value="0.001"/>
         <inertia ixx="1e-09" iyy="1e-09" izz="1e-09" ixy="0" ixz="0" iyz="0"/>
      </inertial>
   </link>
   <joint type="revolute" name="root2ring_pp">
      <parent link="ring_um"/>
      <child link="root2ring_pp_jointbody"/>
      <origin xyz="-7.079094348244037e-17 -1.1114218455696548e-16 2.2466569823203384e-17" rpy="3.552713678800501e-15 -1.5707963267948937 0.0"/>
      <axis xyz="1.887379141862766e-15 -1.0000000000000049 4.1494585545365226e-15"/>
      <limit lower="-0.17453292519943295" upper="2.007128639793479" effort="100" velocity="100"/>
   </joint>
   <joint type="fixed" name="root2ring_pp_offset">
      <parent link="root2ring_pp_jointbody"/>
      <child link="ring_pp"/>
      <origin xyz="-2.1621119931780223e-19 6.062911924869317e-18 4.472658181669709e-17" rpy="0.0 0.0 0.0"/>
   </joint>
   <link name="ring_mp">
      <inertial>
         <origin xyz="0.0013909738898894978 0.00016387532873425497 0.014968668474816213" rpy="0.03291128493942308 -0.020555715782136996 1.1076943559460612"/>
         <mass value="0.003108373341414378"/>
         <inertia ixx="3.251881563114705e-07" iyy="3.238587171666197e-07" izz="4.895669014432085e-08" ixy="0" ixz="0" iyz="0"/>
      </inertial>
      <visual name="ring_mp">
         <origin xyz="0.0013909738898894978 0.00016387532873425497 0.014968668474816213" rpy="0.03291128493942308 -0.020555715782136774 1.107694355946061"/>
         <geometry>
            <mesh filename="package://viz/models/orca2_hand/urdf/converted_ring_mp.stl"/>
         </geometry>
         <material name="white"/>
      </visual>
   </link>
   <link name="ring_pp2mp_jointbody">
      <inertial>
         <origin xyz="0.0 0.0 0.0" rpy="0.0 0.0 0.0"/>
         <mass value="0.001"/>
         <inertia ixx="1e-09" iyy="1e-09" izz="1e-09" ixy="0" ixz="0" iyz="0"/>
      </inertial>
   </link>
   <joint type="revolute" name="ring_pp2mp">
      <parent link="ring_pp"/>
      <child link="ring_pp2mp_jointbody"/>
      <origin xyz="3.376451560558019e-17 2.7849414523275e-16 0.04800000000000019" rpy="1.0269562977782832e-15 8.43769498715119e-15 2.664535259100386e-15"/>
      <axis xyz="-1.9984014443252818e-15 -0.9999999999999992 2.5396351688300456e-15"/>
      <limit lower="0.0" upper="2.0943951023931953" effort="100" velocity="100"/>
   </joint>
   <joint type="fixed" name="ring_pp2mp_offset">
      <parent link="ring_pp2mp_jointbody"/>
      <child link="ring_mp"/>
      <origin xyz="6.5678052108806596e-18 -7.769990288843462e-17 -3.518696938514808e-17" rpy="0.0 0.0 0.0"/>
   </joint>
   <link name="ring_dp">
      <inertial>
         <origin xyz="-1.3890187096631583e-05 0.005054400100332685 -0.00020300962240500135" rpy="1.4604505475177294 -0.03444883339617988 0.0022630734580013634"/>
         <mass value="0.0011385821737687244"/>
         <inertia ixx="5.751980191525933e-08" iyy="5.65392336466142e-08" izz="1.0221302805317223e-08" ixy="0" ixz="0" iyz="0"/>
      </inertial>
      <visual name="ring_dp">
         <origin xyz="-1.3890187096631583e-05 0.005054400100332685 -0.00020300962240500135" rpy="1.4604505475177294 -0.03444883339617988 0.0022630734580013634"/>
         <geometry>
            <mesh filename="package://viz/models/orca2_hand/urdf/converted_ring_dp.stl"/>
         </geometry>
         <material name="white"/>
      </visual>
   </link>
   <link name="ring_mp2dp_jointbody">
      <inertial>
         <origin xyz="0.0 0.0 0.0" rpy="0.0 0.0 0.0"/>
         <mass value="0.001"/>
         <inertia ixx="1e-09" iyy="1e-09" izz="1e-09" ixy="0" ixz="0" iyz="0"/>
      </inertial>
   </link>
   <joint type="revolute" name="ring_mp2dp">
      <parent link="ring_mp"/>
      <child link="ring_mp2dp_jointbody"/>
      <origin xyz="0.0009999999999997717 -1.8811635228396815e-16 0.028000000000000053" rpy="1.5707963267948908 4.6629367034256575e-15 1.5707963267948934"/>
      <axis xyz="-1.0000000000000004 -2.213507155346406e-15 3.656797087359109e-15"/>
      <limit lower="0.0" upper="1.3089969389957472" effort="100" velocity="100"/>
   </joint>
   <joint type="fixed" name="ring_mp2dp_offset">
      <parent link="ring_mp2dp_jointbody"/>
      <child link="ring_dp"/>
      <origin xyz="-1.2738647990931297e-16 -1.203371633436387e-16 1.0888894666999057e-17" rpy="0.0 0.0 0.0"/>
   </joint>
   <link name="ring_fingertip">
      <inertial>
         <origin xyz="0.0 0.02 -0.001306" rpy="0.0 0.0 0.0"/>
         <mass value="0.0"/>
         <inertia ixx="0.0" iyy="0.0" izz="0.0" ixy="0" ixz="0" iyz="0"/>
      </inertial>
   </link>
   <link name="ring_dp2ring_fingertip_fixed_jointbody">
      <inertial>
         <origin xyz="0.0 0.0 0.0" rpy="0.0 0.0 0.0"/>
         <mass value="0.001"/>
         <inertia ixx="1e-09" iyy="1e-09" izz="1e-09" ixy="0" ixz="0" iyz="0"/>
      </inertial>
   </link>
   <joint type="fixed" name="ring_dp2ring_fingertip_fixed">
      <parent link="ring_dp"/>
      <child link="ring_dp2ring_fingertip_fixed_jointbody"/>
      <origin xyz="0.0 0.02 -0.001306" rpy="0.0 0.0 0.0"/>
   </joint>
   <joint type="fixed" name="ring_dp2ring_fingertip_fixed_offset">
      <parent link="ring_dp2ring_fingertip_fixed_jointbody"/>
      <child link="ring_fingertip"/>
      <origin xyz="-0.0 -0.0 -0.0" rpy="0.0 0.0 0.0"/>
   </joint>
   <link name="thumb_base">
      <inertial>
         <origin xyz="0.009146054539715962 5.296465019593427e-05 2.762635867494183e-06" rpy="1.5609087911830748 -1.5306517014896879 1.599685076742187"/>
         <mass value="0.004462909298601651"/>
         <inertia ixx="3.475601337005608e-07" iyy="3.0144183100196083e-07" izz="1.505553164619097e-07" ixy="0" ixz="0" iyz="0"/>
      </inertial>
      <visual name="thumb_base">
         <origin xyz="0.009146054539715962 5.296465019593427e-05 2.762635867494183e-06" rpy="1.5609087911830748 -1.5306517014896879 1.599685076742187"/>
         <geometry>
            <mesh filename="package://viz/models/orca2_hand/urdf/converted_thumb_base.stl"/>
         </geometry>
         <material name="white"/>
      </visual>
   </link>
   <link name="root2thumb_base_jointbody">
      <inertial>
         <origin xyz="0.0 0.0 0.0" rpy="0.0 0.0 0.0"/>
         <mass value="0.001"/>
         <inertia ixx="1e-09" iyy="1e-09" izz="1e-09" ixy="0" ixz="0" iyz="0"/>
      </inertial>
   </link>
   <joint type="revolute" name="root2thumb_base">
      <parent link="palm"/>
      <child link="root2thumb_base_jointbody"/>
      <origin xyz="-0.019336685560293027 0.007354881795979842 -0.02738447811197527" rpy="0.8650692244264337 0.5077476451224614 -0.8026267442856483"/>
      <axis xyz="3.0531133177191805e-16 4.440892098500626e-15 0.9999999999999966"/>
      <limit lower="-1.3089969389957472" upper="1.3089969389957472" effort="100" velocity="100"/>
   </joint>
   <joint type="fixed" name="root2thumb_base_offset">
      <parent link="root2thumb_base_jointbody"/>
      <child link="thumb_base"/>
      <origin xyz="-0.016900000000000383 -1.2663481374630692e-16 -1.857238321467669e-16" rpy="0.0 0.0 0.0"/>
   </joint>
   <link name="thumb_pp">
      <inertial>
         <origin xyz="0.011052064663332051 1.6203312209423124e-05 3.4258699652190326e-05" rpy="0.033962151123506645 -1.5659078669478594 3.111696080587949"/>
         <mass value="0.005199376106974465"/>
         <inertia ixx="5.397346277253312e-07" iyy="4.918763012442806e-07" izz="1.6602184630010976e-07" ixy="0" ixz="0" iyz="0"/>
      </inertial>
      <visual name="thumb_pp">
         <origin xyz="0.011052064663332051 1.6203312209423124e-05 3.4258699652190326e-05" rpy="0.033962151123505535 -1.5659078669478592 3.1116960805879503"/>
         <geometry>
            <mesh filename="package://viz/models/orca2_hand/urdf/converted_thumb_pp.stl"/>
         </geometry>
         <material name="white"/>
      </visual>
   </link>
   <link name="thumb_base2pp_jointbody">
      <inertial>
         <origin xyz="0.0 0.0 0.0" rpy="0.0 0.0 0.0"/>
         <mass value="0.001"/>
         <inertia ixx="1e-09" iyy="1e-09" izz="1e-09" ixy="0" ixz="0" iyz="0"/>
      </inertial>
   </link>
   <joint type="revolute" name="thumb_base2pp">
      <parent link="thumb_base"/>
      <child link="thumb_base2pp_jointbody"/>
      <origin xyz="5.793976409762536e-16 1.6683717543749632e-16 1.0319280192681784e-16" rpy="-1.5707963267949 -3.1086244689504383e-15 -1.4654943925052066e-14"/>
      <axis xyz="-1.5015766408055242e-14 -5.745404152435185e-15 0.999999999999998"/>
      <limit lower="-0.7853981633974483" upper="0.7853981633974483" effort="100" velocity="100"/>
   </joint>
   <joint type="fixed" name="thumb_base2pp_offset">
      <parent link="thumb_base2pp_jointbody"/>
      <child link="thumb_pp"/>
      <origin xyz="-0.023000000000001106 -1.6393136847980827e-16 -5.915407053080912e-16" rpy="0.0 0.0 0.0"/>
   </joint>
   <link name="thumb_mp">
      <inertial>
         <origin xyz="0.0008724539758762056 2.4727438746056388e-05 0.014659312447177586" rpy="-0.0003364028998661733 -0.01711516449902417 0.008877420129339876"/>
         <mass value="0.004529151319492986"/>
         <inertia ixx="5.870714715027592e-07" iyy="5.782548760385939e-07" izz="9.130226060122018e-08" ixy="0" ixz="0" iyz="0"/>
      </inertial>
      <visual name="thumb_mp">
         <origin xyz="0.0008724539758762056 2.4727438746056388e-05 0.014659312447177586" rpy="-0.0003364028998661733 -0.01711516449902417 0.008877420129339876"/>
         <geometry>
            <mesh filename="package://viz/models/orca2_hand/urdf/converted_thumb_mp.stl"/>
         </geometry>
         <material name="white"/>
      </visual>
   </link>
   <link name="thumb_pp2mp_jointbody">
      <inertial>
         <origin xyz="0.0 0.0 0.0" rpy="0.0 0.0 0.0"/>
         <mass value="0.001"/>
         <inertia ixx="1e-09" iyy="1e-09" izz="1e-09" ixy="0" ixz="0" iyz="0"/>
      </inertial>
   </link>
   <joint type="revolute" name="thumb_pp2mp">
      <parent link="thumb_pp"/>
      <child link="thumb_pp2mp_jointbody"/>
      <origin xyz="1.1005837463337052e-15 1.7945721429140714e-16 6.444859462348048e-16" rpy="3.141592653589785 1.5707963267948641 0.0"/>
      <axis xyz="1.9984014443252818e-14 -0.9999999999999943 -1.1435297153639112e-14"/>
      <limit lower="-0.17453292519943295" upper="1.5707963267948966" effort="100" velocity="100"/>
   </joint>
   <joint type="fixed" name="thumb_pp2mp_offset">
      <parent link="thumb_pp2mp_jointbody"/>
      <child link="thumb_mp"/>
      <origin xyz="-8.28264772479016e-18 5.058868245246064e-18 -9.571993728557986e-17" rpy="0.0 0.0 0.0"/>
   </joint>
   <link name="thumb_dp">
      <inertial>
         <origin xyz="1.0065826614441387e-05 0.006272335517680365 -0.00010113404865312324" rpy="1.4779757020900604 0.03179381852807506 -0.0019765844728094617"/>
         <mass value="0.001814128231283667"/>
         <inertia ixx="1.4115416029381981e-07" iyy="1.3962326809815754e-07" izz="2.257709422103513e-08" ixy="0" ixz="0" iyz="0"/>
      </inertial>
      <visual name="thumb_dp">
         <origin xyz="1.0065826614441387e-05 0.006272335517680365 -0.00010113404865312324" rpy="1.4779757020900601 0.03179381852807506 -0.0019765844728094617"/>
         <geometry>
            <mesh filename="package://viz/models/orca2_hand/urdf/converted_thumb_dp.stl"/>
         </geometry>
         <material name="white"/>
      </visual>
   </link>
   <link name="thumb_mp2dp_jointbody">
      <inertial>
         <origin xyz="0.0 0.0 0.0" rpy="0.0 0.0 0.0"/>
         <mass value="0.001"/>
         <inertia ixx="1e-09" iyy="1e-09" izz="1e-09" ixy="0" ixz="0" iyz="0"/>
      </inertial>
   </link>
   <joint type="revolute" name="thumb_mp2dp">
      <parent link="thumb_mp"/>
      <child link="thumb_mp2dp_jointbody"/>
      <origin xyz="4.2281847092080333e-16 4.4349038165432816e-16 0.0299999999999999" rpy="1.5707963267949152 -7.549516567451064e-15 1.5707963267949303"/>
      <axis xyz="0.9999999999999917 6.494804694057166e-15 1.62231339473351e-14"/>
      <limit lower="-1.7453292519943295" upper="0.0" effort="100" velocity="100"/>
   </joint>
   <joint type="fixed" name="thumb_mp2dp_offset">
      <parent link="thumb_mp2dp_jointbody"/>
      <child link="thumb_dp"/>
      <origin xyz="1.2741892527574519e-17 -1.005995402266765e-16 -9.397995200594752e-17" rpy="0.0 0.0 0.0"/>
   </joint>
   <link name="thumb_fingertip">
      <inertial>
         <origin xyz="0.0 0.02425 -0.001189" rpy="0.0 0.0 0.0"/>
         <mass value="0.0"/>
         <inertia ixx="0.0" iyy="0.0" izz="0.0" ixy="0" ixz="0" iyz="0"/>
      </inertial>
   </link>
   <link name="thumb_dp2thumb_fingertip_fixed_jointbody">
      <inertial>
         <origin xyz="0.0 0.0 0.0" rpy="0.0 0.0 0.0"/>
         <mass value="0.001"/>
         <inertia ixx="1e-09" iyy="1e-09" izz="1e-09" ixy="0" ixz="0" iyz="0"/>
      </inertial>
   </link>
   <joint type="fixed" name="thumb_dp2thumb_fingertip_fixed">
      <parent link="thumb_dp"/>
      <child link="thumb_dp2thumb_fingertip_fixed_jointbody"/>
      <origin xyz="0.0 0.02425 -0.001189" rpy="0.0 0.0 0.0"/>
   </joint>
   <joint type="fixed" name="thumb_dp2thumb_fingertip_fixed_offset">
      <parent link="thumb_dp2thumb_fingertip_fixed_jointbody"/>
      <child link="thumb_fingertip"/>
      <origin xyz="-0.0 -0.0 -0.0" rpy="0.0 0.0 0.0"/>
   </joint>
   <link name="middle_um">
      <inertial>
         <origin xyz="0.006732763304155957 4.001088863436687e-09 -2.0258619702217643e-05" rpy="-3.131684616200393 -1.561854856603541 -0.009908433449917098"/>
         <mass value="0.002607186033198995"/>
         <inertia ixx="1.3807074528604164e-07" iyy="1.1778104249469416e-07" izz="6.49217043247213e-08" ixy="0" ixz="0" iyz="0"/>
      </inertial>
      <visual name="middle_um">
         <origin xyz="0.006732763304155957 4.001088863436687e-09 -2.0258619702217643e-05" rpy="-3.131684616200393 -1.561854856603541 -0.009908433449916876"/>
         <geometry>
            <mesh filename="package://viz/models/orca2_hand/urdf/converted_middle_um.stl"/>
         </geometry>
         <material name="white"/>
      </visual>
   </link>
   <link name="middle_abd_jointbody">
      <inertial>
         <origin xyz="0.0 0.0 0.0" rpy="0.0 0.0 0.0"/>
         <mass value="0.001"/>
         <inertia ixx="1e-09" iyy="1e-09" izz="1e-09" ixy="0" ixz="0" iyz="0"/>
      </inertial>
   </link>
   <joint type="revolute" name="middle_abd">
      <parent link="palm"/>
      <child link="middle_abd_jointbody"/>
      <origin xyz="-0.0009621394664390589 3.819301119317218e-18 0.0389585438155554" rpy="1.5707963267948968 1.5707963267948948 0.0"/>
      <axis xyz="-1.609823385706477e-15 -5.551115123125783e-17 0.9999999999999982"/>
      <limit lower="-0.4363323129985824" upper="0.6108652381980153" effort="100" velocity="100"/>
   </joint>
   <joint type="fixed" name="middle_abd_offset">
      <parent link="middle_abd_jointbody"/>
      <child link="middle_um"/>
      <origin xyz="-0.014399999999999937 -2.168404344971009e-17 -2.3418766925686896e-17" rpy="0.0 0.0 0.0"/>
   </joint>
   <link name="middle_pp">
      <inertial>
         <origin xyz="0.0008879048431632835 -2.537949357785257e-05 0.026668810452510044" rpy="-0.0011314495857910837 -0.009859569454313544 0.029169093210231874"/>
         <mass value="0.007199054377400034"/>
         <inertia ixx="2.0187701497182777e-06" iyy="2.002065106814579e-06" izz="1.361803516902417e-07" ixy="0" ixz="0" iyz="0"/>
      </inertial>
      <visual name="middle_pp">
         <origin xyz="0.0008879048431632835 -2.537949357785257e-05 0.026668810452510044" rpy="-0.0011314495857910837 -0.009859569454313544 0.029169093210231874"/>
         <geometry>
            <mesh filename="package://viz/models/orca2_hand/urdf/converted_middle_pp.stl"/>
         </geometry>
         <material name="white"/>
      </visual>
   </link>
   <link name="root2middle_pp_jointbody">
      <inertial>
         <origin xyz="0.0 0.0 0.0" rpy="0.0 0.0 0.0"/>
         <mass value="0.001"/>
         <inertia ixx="1e-09" iyy="1e-09" izz="1e-09" ixy="0" ixz="0" iyz="0"/>
      </inertial>
   </link>
   <joint type="revolute" name="root2middle_pp">
      <parent link="middle_um"/>
      <child link="root2middle_pp_jointbody"/>
      <origin xyz="-2.7755575615628883e-17 7.9797279894933e-17 1.2326378958831793e-17" rpy="-1.7763568394002505e-15 -1.5707963267948957 0.0"/>
      <axis xyz="4.440892098500626e-16 -0.9999999999999989 -1.6139120735855316e-15"/>
      <limit lower="-0.17453292519943295" upper="2.007128639793479" effort="100" velocity="100"/>
   </joint>
   <joint type="fixed" name="root2middle_pp_offset">
      <parent link="root2middle_pp_jointbody"/>
      <child link="middle_pp"/>
      <origin xyz="4.789446380758887e-20 2.407412430484045e-35 4.887917868404888e-35" rpy="0.0 0.0 0.0"/>
   </joint>
   <link name="middle_mp">
      <inertial>
         <origin xyz="0.0013909738898894978 0.00016387532873425497 0.014968668474816213" rpy="0.03291128493942308 -0.020555715782136996 1.1076943559460612"/>
         <mass value="0.003108373341414378"/>
         <inertia ixx="3.251881563114705e-07" iyy="3.238587171666197e-07" izz="4.895669014432085e-08" ixy="0" ixz="0" iyz="0"/>
      </inertial>
      <visual name="middle_mp">
         <origin xyz="0.0013909738898894978 0.00016387532873425497 0.014968668474816213" rpy="0.03291128493942308 -0.020555715782136774 1.107694355946061"/>
         <geometry>
            <mesh filename="package://viz/models/orca2_hand/urdf/converted_middle_mp.stl"/>
         </geometry>
         <material name="white"/>
      </visual>
   </link>
   <link name="middle_pp2mp_jointbody">
      <inertial>
         <origin xyz="0.0 0.0 0.0" rpy="0.0 0.0 0.0"/>
         <mass value="0.001"/>
         <inertia ixx="1e-09" iyy="1e-09" izz="1e-09" ixy="0" ixz="0" iyz="0"/>
      </inertial>
   </link>
   <joint type="revolute" name="middle_pp2mp">
      <parent link="middle_pp"/>
      <child link="middle_pp2mp_jointbody"/>
      <origin xyz="-1.6582768499728945e-17 1.0489639593821613e-17 0.04800000000000033" rpy="-1.0007424131434651e-16 7.993605777301127e-15 -3.3306690738754834e-16"/>
      <axis xyz="-3.3306690738754696e-16 -1.0000000000000029 -3.9403654086199957e-16"/>
      <limit lower="0.0" upper="2.0943951023931953" effort="100" velocity="100"/>
   </joint>
   <joint type="fixed" name="middle_pp2mp_offset">
      <parent link="middle_pp2mp_jointbody"/>
      <child link="middle_mp"/>
      <origin xyz="8.359114758843884e-17 9.540979117872525e-18 1.3877787807815292e-17" rpy="0.0 0.0 0.0"/>
   </joint>
   <link name="middle_dp">
      <inertial>
         <origin xyz="-1.3890187096631583e-05 0.005054400100332685 -0.00020300962240500135" rpy="1.4604505475177294 -0.03444883339617988 0.0022630734580013634"/>
         <mass value="0.0011385821737687244"/>
         <inertia ixx="5.751980191525933e-08" iyy="5.65392336466142e-08" izz="1.0221302805317223e-08" ixy="0" ixz="0" iyz="0"/>
      </inertial>
      <visual name="middle_dp">
         <origin xyz="-1.3890187096631583e-05 0.005054400100332685 -0.00020300962240500135" rpy="1.4604505475177294 -0.03444883339617988 0.0022630734580013634"/>
         <geometry>
            <mesh filename="package://viz/models/orca2_hand/urdf/converted_middle_dp.stl"/>
         </geometry>
         <material name="white"/>
      </visual>
   </link>
   <link name="middle_mp2dp_jointbody">
      <inertial>
         <origin xyz="0.0 0.0 0.0" rpy="0.0 0.0 0.0"/>
         <mass value="0.001"/>
         <inertia ixx="1e-09" iyy="1e-09" izz="1e-09" ixy="0" ixz="0" iyz="0"/>
      </inertial>
   </link>
   <joint type="revolute" name="middle_mp2dp">
      <parent link="middle_mp"/>
      <child link="middle_mp2dp_jointbody"/>
      <origin xyz="0.0009999999999996654 -3.469446951953682e-18 0.027999999999999824" rpy="1.5707963267948888 -8.881784197001252e-16 1.5707963267948977"/>
      <axis xyz="-0.9999999999999996 6.386501543029423e-16 -1.1761641417377724e-15"/>
      <limit lower="0.0" upper="1.3089969389957472" effort="100" velocity="100"/>
   </joint>
   <joint type="fixed" name="middle_mp2dp_offset">
      <parent link="middle_mp2dp_jointbody"/>
      <child link="middle_dp"/>
      <origin xyz="1.4745149545802805e-17 1.4791141972893971e-31 1.3769367590565884e-16" rpy="0.0 0.0 0.0"/>
   </joint>
   <link name="middle_fingertip">
      <inertial>
         <origin xyz="0.0 0.02 -0.001306" rpy="0.0 0.0 0.0"/>
         <mass value="0.0"/>
         <inertia ixx="0.0" iyy="0.0" izz="0.0" ixy="0" ixz="0" iyz="0"/>
      </inertial>
   </link>
   <link name="middle_dp2middle_fingertip_fixed_jointbody">
      <inertial>
         <origin xyz="0.0 0.0 0.0" rpy="0.0 0.0 0.0"/>
         <mass value="0.001"/>
         <inertia ixx="1e-09" iyy="1e-09" izz="1e-09" ixy="0" ixz="0" iyz="0"/>
      </inertial>
   </link>
   <joint type="fixed" name="middle_dp2middle_fingertip_fixed">
      <parent link="middle_dp"/>
      <child link="middle_dp2middle_fingertip_fixed_jointbody"/>
      <origin xyz="0.0 0.02 -0.001306" rpy="0.0 0.0 0.0"/>
   </joint>
   <joint type="fixed" name="middle_dp2middle_fingertip_fixed_offset">
      <parent link="middle_dp2middle_fingertip_fixed_jointbody"/>
      <child link="middle_fingertip"/>
      <origin xyz="-0.0 -0.0 -0.0" rpy="0.0 0.0 0.0"/>
   </joint>
   <material name="white">
      <color rgba="1 1 1 1"/>
   </material>
</robot>
