<mujoco model="right_orca2">

	<body name="root" euler="0 0 0">

		<body name="tower" pos="0.0 0.0 0.0" quat="1.0 0.0 0.0 0.0">
            <body name="palm" pos="0.193999986406645 -3.686916491009634e-05 0.00199999999999996" quat="0.7071067331267782 0.00026070438296540136 0.7071067331267784 -0.0002607043829654448">
                <joint name="tower2root" pos="0.0019999999999999996 1.0164395367051604e-20 -0.04999999999999999" axis="0.9999999999999993 6.127748595140475e-17 6.118716649654125e-17" range="-1.3962634015954636 1.3962634015954636"/>
				<geom mesh="palm_tower"/>
				

					<body name="index_um" pos="-0.024529529905114904 0.0015685968794286623 0.049739086616754365" quat="0.5175673106841135 0.5648194489683283 0.43421907836698487 -0.47387430924292245">
						<body name="index_pp" pos="-3.7277721010885605e-14 1.5827528920976977e-13 -1.3896815702055568e-14" quat="0.7064409996808589 -7.180922523275513e-13 -0.7077719364102442 -7.412404023909858e-13">
							<body name="index_mp" pos="-2.1467203015212988e-17 9.324138683375338e-18 0.03999999999999995" quat="1.0000000000000004 -6.938893903907228e-18 -1.6653345369377348e-16 0.0">
								<body name="index_dp" pos="0.0009927185295307188 -0.01099999999999999 0.03700728147046931" quat="-0.7071067811865469 5.611830444784971e-16 -1.5785983631388945e-16 -0.7071067811865476">
									<body name="index_fingertip" pos="0.011 0.0 0.022" euler="0 0 0">
									</body>
									<joint name="index_mp2dp" pos="0.01099999999999995 -7.281470469246501e-06 -0.009007281470469294" axis="-0.9999999999999998 -1.1796119636642288e-16 -1.946657895643411e-15" range="0.0 1.3089969389957472"/>
									<geom mesh="index_dp"/>
								</body>
								<joint name="index_pp2mp" pos="-1.9461750163187066e-17 -3.195966925249782e-17 -5.1027793401258624e-17" axis="1.0547118733938987e-15 -0.9999999999999989 -9.020562075079397e-16" range="0.0 2.0943951023931953"/>
								<geom mesh="index_mp"/>
							</body>
							<joint name="root2index_pp" pos="-9.357535447968366e-19 -9.360525909273759e-18 -1.2460153634354755e-17" axis="3.175237850427948e-14 -1.0000000000000018 -2.0646956366832114e-12" range="-0.17453292519943295 2.007128639793479"/>
							<geom mesh="index_pp"/>
						</body>
						<joint name="index_abd" pos="0.014399999999999979 1.1275702593849246e-17 4.7704895589362195e-18" axis="-1.80855330711438e-13 -2.220446049250313e-16 0.9999999999999967" range="-0.4363323129985824 0.6108652381980153"/>
						<geom mesh="index_um"/>
					</body>


					<body name="pinky_um" pos="0.04979641298344026 0.007437708668019195 0.02714929329024474" quat="0.39165831717623767 0.22191805252953492 0.6734694086488737 -0.5863404268531313">
						<body name="pinky_pp" pos="2.028230347434807e-17 7.612199969945414e-18 2.3533653782354537e-17" quat="0.7065579686474562 2.220446049250313e-16 -0.7076551681015123 -1.6653345369377348e-16">
							<body name="pinky_mp" pos="-1.9081958235744878e-17 -4.119968255444917e-17 0.030000000000000054" quat="1.0 -2.7755575615628914e-17 -2.7755575615628914e-17 0.0">
								<body name="pinky_dp" pos="0.000992718529542678 -0.011000000000012954 0.03700728147046726" quat="-0.7071067811865471 -1.1860651349948625e-13 -6.58501031480796e-15 -0.7071067811865483">
									<body name="pinky_fingertip" pos="0.011 0.0 0.022" euler="0 0 0">
									</body>
									<joint name="pinky_mp2dp" pos="0.011000000000000044 -7.281470469290411e-06 -0.00900728147046922" axis="-0.9999999999999996 2.3037127760972e-15 1.584097436557741e-13" range="0.0 1.3089969389957472"/>
									<geom mesh="pinky_dp"/>
								</body>
								<joint name="pinky_pp2mp" pos="-1.171869695207721e-18 8.725104538385514e-18 2.4424879789821522e-17" axis="-4.440892098500626e-16 -1.0000000000000004 -8.326672684688674e-17" range="0.0 2.0943951023931953"/>
								<geom mesh="pinky_mp"/>
							</body>
							<joint name="root2pinky_pp" pos="3.833184058085544e-18 -7.922763782835389e-18 -1.4973823299787632e-17" axis="-3.885780586188048e-16 -1.0000000000000004 -2.636779683484747e-16" range="-0.17453292519943295 2.007128639793479"/>
							<geom mesh="pinky_pp"/>
						</body>
						<joint name="pinky_abd" pos="0.014400000000000012 -2.211772431870429e-17 1.5178830414797062e-17" axis="-1.942890293094024e-16 6.661338147750939e-16 -1.0000000000000004" range="-0.6108652381980153 0.4363323129985824"/>
						<geom mesh="pinky_um"/>
					</body>

					<body name="ring_um" pos="0.023409547989986016 0.001707590946479374 0.04449519261795145" quat="0.4544828874453351 0.4055406609370029 0.5792553602054793 -0.5417059211595832">
						<body name="ring_pp" pos="8.620933045430902e-16 -6.59189781714435e-14 -5.6109241777461314e-15" quat="0.7065050981872533 3.4389158187764224e-13 -0.7077079526438984 3.289035710452026e-13">
							<body name="ring_mp" pos="-8.239936510889834e-18 7.37257477290143e-18 0.04800000000000008" quat="0.9999999999999998 -4.163336342344337e-17 1.1102230246251565e-16 -2.220446049250313e-16">
								<body name="ring_dp" pos="0.0009927185295307102 -0.011000000000000005 0.03700728147046929" quat="-0.7071067811865471 -5.724587470723463e-16 1.5300261058115439e-15 -0.7071067811865472">
									<body name="ring_fingertip" pos="0.011 0.0 0.022" euler="0 0 0">


									</body>
									<joint name="ring_mp2dp" pos="0.011000000000000136 -7.2814704693049395e-06 -0.009007281470469263" axis="-1.0000000000000004 9.71445146547012e-17 4.7009379895712744e-15" range="0.0 1.3089969389957472"/>
									<geom mesh="ring_dp"/>
								</body>
								<joint name="ring_pp2mp" pos="2.4797730845642552e-17 9.545841872561936e-17 2.5561932479781495e-17" axis="5.551115123125783e-17 -0.9999999999999998 1.6514567491299204e-15" range="0.0 2.0943951023931953"/>
								<geom mesh="ring_mp"/>
							</body>
							<joint name="root2ring_pp" pos="9.795286269233676e-19 1.4465518891423126e-19 -1.4329772049885697e-17" axis="2.1538326677728037e-14 -1.0000000000000016 9.536885170469134e-13" range="-0.17453292519943295 2.007128639793479"/>
							<geom mesh="ring_pp"/>
						</body>
						<joint name="ring_abd" pos="0.014400000000000029 -3.5561831257524545e-17 -8.239936510889834e-18" axis="-8.004708007547379e-14 -1.9984014443252818e-14 0.9999999999999978" range="-0.4363323129985824 0.6108652381980153"/>
						<geom mesh="ring_um"/>
					</body>

								
					<body name="thumb_base" pos="-0.029597736635895423 0.017975734031793388 -0.019167524381491743" quat="-0.46257424952983467 0.7678583570172343 -0.4401987728653877 -0.05141641370724577">
						<body name="thumb_pp" pos="-0.0230000000000005 5.715913853343579e-16 1.0722759485881639e-16" quat="0.5372996083468241 0.8433914458128913 -1.3322676295501878e-15 6.938893903907228e-16">
							<body name="thumb_mp" pos="1.2074684138542838e-15 1.7919654376385695e-16 6.544144197250373e-16" quat="-2.9976021664879227e-15 -0.7071067811865377 1.1102230246251565e-15 0.7071067811865492">
								<body name="thumb_dp" pos="-7.2814704692729555e-06 -0.01099999999999977 0.039007281470469085" quat="-0.7071067811865528 -5.440092820663267e-15 3.635980405647388e-15 -0.7071067811865498">
									<body name="thumb_fingertip" pos="0.011 0.0 0.022" euler="0 0 0">
									</body>
									<joint name="thumb_mp2dp" pos="0.011000000000000175 -7.281470469432116e-06 -0.009007281470469333" axis="-0.9999999999999958 2.9976021664879227e-15 5.287437154777308e-15" range="0.0 1.57"/>
									<geom mesh="thumb_dp"/>
								</body>
								<joint name="thumb_pp2mp" pos="6.8988979146713415e-18 2.155793885708645e-17 2.0127088287987651e-16" axis="-6.8833827526759706e-15 -0.9999999999999959 -7.993605777301127e-15" range="-0.17453292519943295 1.5707963267948966"/>
								<geom mesh="thumb_mp"/>
							</body>
							<joint name="thumb_base2pp" pos="0.023000000000001172 9.367506770274758e-17 3.499533562240087e-16" axis="1.0824674490095276e-15 -0.42261826174070033 -0.9063077870366472" range="-0.7853981633974483 0.7853981633974483"/>
							<geom mesh="thumb_pp"/>
						</body>
						<joint name="root2thumb_base" pos="0.016900000000000366 6.505213034913027e-17 1.8106176280507924e-16" axis="1.1657341758564144e-15 -2.220446049250313e-15 -0.9999999999999962" range="-1.3089969389957472 1.3089969389957472"/>
						<geom mesh="thumb_base"/>
					</body>

					<body name="middle_um" pos="-0.0009621394664390685 2.375080384101058e-18 0.053358543815555326" quat="0.5000000000000004 0.49999999999999983 0.5 -0.5000000000000008">
						<body name="middle_pp" pos="-4.1633372091515825e-17 2.7755575615628864e-17 -3.594699893231231e-21" quat="0.706460881922205 -2.220446049250313e-16 -0.7077520909991706 -2.220446049250313e-16">
							<body name="middle_mp" pos="-8.63312920500528e-17 -9.330914946953373e-18 0.048000000000000154" quat="1.0 3.0574501264091225e-17 0.0 0.0">
								<body name="middle_dp" pos="0.0009927185295347972 -0.011000000000000064 0.03700728147046922" quat="-0.7071067811865478 -1.6290517112355074e-14 -1.5878195026158837e-14 -0.7071067811865477">
									<body name="middle_fingertip" pos="0.011 0.0 0.022" euler="0 0 0">
									</body>
									<joint name="middle_mp2dp" pos="0.011000000000000034 -7.28147046937894e-06 -0.009007281470469267" axis="-1.0000000000000002 -3.2838929933875956e-17 5.315090385248316e-16" range="0.0 1.3089969389957472"/>
									<geom mesh="middle_dp"/>
								</body>
								<joint name="middle_pp2mp" pos="6.817933558779142e-17 6.938893903907302e-18 -7.4224300060933e-20" axis="-1.6653345369377348e-16 -1.0000000000000004 9.75781955236954e-18" range="0.0 2.0943951023931953"/>
								<geom mesh="middle_mp"/>
							</body>
							<joint name="root2middle_pp" pos="-1.5108221092759517e-20 9.7018720948507e-33 -1.3877779583938463e-17" axis="-1.1102230246251565e-16 -1.0000000000000009 9.75781955236954e-18" range="-0.17453292519943295 2.007128639793479"/>
							<geom mesh="middle_pp"/>
						</body>
						<joint name="middle_abd" pos="0.014400000000000015 2.0816681711721685e-17 -2.0383000842727483e-17" axis="1.3877787807814457e-15 1.1102230246251565e-16 0.9999999999999987" range="-0.4363323129985824 0.6108652381980153"/>
						<geom mesh="middle_um"/>
					</body>

            </body>

            <geom mesh="tower"/>
		</body>
    </body>

</mujoco>